Workbook

Sheet README
A1: PELOBROSSSSS - WORKOUT TRACKER
A2: Complete training log, January 16 - July 21, 2026
A4: WHAT'S IN HERE
A5: Sets | B5: One row per set lifted. This is the source of truth - everything else reads from it.
A6: Cardio | B6: One row per cardio bout (elliptical, treadmill, stairs, rowing, runs).
A7: PR Summary | B7: Auto-calculated best weight, date it was first hit, and most recent performance per exercise.
A8: Progress | B8: Top working weight per exercise per session. Feeds the charts.
A9: Charts | B9: Progression lines for the main lifts.
A11: HOW TO ADD A NEW WORKOUT
A12: 1. | B12: Go to the Sets tab and type new rows directly underneath the last one.
A13: 2. | B13: Add the date to column A of the Progress tab (next empty row) and drag the formulas across.
A14: 3. | B14: Log cardio on the Cardio tab. PR Summary updates itself.
B15: All formulas are pre-extended to row 2000, so there is room for roughly two more years of logging.
A17: EXAMPLE ROW (Sets tab) - copy this format
A18: Date | B18: Day | C18: Workout Type | D18: Exercise | E18: Equipment | F18: Unit | G18: Set # | H18: Weight | I18: Reps | J18: Warmup? | K18: Volume | L18: Key | M18: Notes
A19: 46226 | B19: Thu | C19: Push | D19: Bench Press | E19: Smith | F19: lbs | G19: 4 | H19: 110 | I19: 8 | J19: N | K19: (formula) | L19: (formula) | M19: felt strong
A21: CONVENTIONS
A22: Weight | B22: Dumbbell weights are PER HAND. Smith machine and barbell weights are TOTAL.
A23: Unit | B23: lbs for dumbbells / Smith / machines. kg for the cable stack. BW for bodyweight moves.
A24: Warmup? | B24: Y = warmup set (excluded from PR and volume calcs). N = working set.
A25: Reps | B25: Defaults to 8 unless a different number was logged.
A26: Cardio | B26: All indoor cycling is logged as 'Elliptical' per longstanding preference.
A27: Volume | B27: Weight x Reps for working sets. For bodyweight moves it just counts reps.
A29: DATA NOTES
A30: Approximate dates | B30: A handful of February and early-April sessions were reconstructed from a transfer document
B31: and carry an estimated date. They are flagged in the Notes column of the Sets tab.
A32: Missing period | B32: No sessions logged Mar 1 - Apr 4 (knee injury period) or Jun 29 - Jul 8 (vacation).
A33: Partial logs | B33: Two New Orleans hotel-gym sessions (Jun 7-8) have incomplete weight data.
A34: Source | B34: All data transcribed from the coaching conversation log.

Sheet Sets
A1: Date | B1: Day | C1: Workout Type | D1: Exercise | E1: Equipment | F1: Unit | G1: Set # | H1: Weight | I1: Reps | J1: Warmup? | K1: Volume | L1: Key | M1: Notes
A2: 46039 | B2: Sat | C2: Legs | D2: Squats | E2: Smith | F2: lbs | G2: 1 | H2: 50 | I2: 8 | J2: N | K2: =IF($J2="Y","",IF($F2="BW",$I2,$H2*$I2)) -> 400 | L2: =$D2&"|"&$H2 -> Squats|50
A3: 46039 | B3: Sat | C3: Legs | D3: Squats | E3: Smith | F3: lbs | G3: 2 | H3: 50 | I3: 8 | J3: N | K3: =IF($J3="Y","",IF($F3="BW",$I3,$H3*$I3)) -> 400 | L3: =$D3&"|"&$H3 -> Squats|50
A4: 46039 | B4: Sat | C4: Legs | D4: Squats | E4: Smith | F4: lbs | G4: 3 | H4: 50 | I4: 8 | J4: N | K4: =IF($J4="Y","",IF($F4="BW",$I4,$H4*$I4)) -> 400 | L4: =$D4&"|"&$H4 -> Squats|50
A5: 46039 | B5: Sat | C5: Legs | D5: RDLs | E5: Smith | F5: lbs | G5: 1 | H5: 20 | I5: 8 | J5: N | K5: =IF($J5="Y","",IF($F5="BW",$I5,$H5*$I5)) -> 160 | L5: =$D5&"|"&$H5 -> RDLs|20
A6: 46039 | B6: Sat | C6: Legs | D6: RDLs | E6: Smith | F6: lbs | G6: 2 | H6: 20 | I6: 8 | J6: N | K6: =IF($J6="Y","",IF($F6="BW",$I6,$H6*$I6)) -> 160 | L6: =$D6&"|"&$H6 -> RDLs|20
A7: 46039 | B7: Sat | C7: Legs | D7: RDLs | E7: Smith | F7: lbs | G7: 3 | H7: 20 | I7: 8 | J7: N | K7: =IF($J7="Y","",IF($F7="BW",$I7,$H7*$I7)) -> 160 | L7: =$D7&"|"&$H7 -> RDLs|20
A8: 46039 | B8: Sat | C8: Legs | D8: Calf Raises (Smith) | E8: Smith | F8: lbs | G8: 1 | H8: 20 | I8: 15 | J8: N | K8: =IF($J8="Y","",IF($F8="BW",$I8,$H8*$I8)) -> 300 | L8: =$D8&"|"&$H8 -> Calf Raises (Smith)|20
A9: 46039 | B9: Sat | C9: Legs | D9: Calf Raises (Smith) | E9: Smith | F9: lbs | G9: 2 | H9: 20 | I9: 15 | J9: N | K9: =IF($J9="Y","",IF($F9="BW",$I9,$H9*$I9)) -> 300 | L9: =$D9&"|"&$H9 -> Calf Raises (Smith)|20
A10: 46039 | B10: Sat | C10: Legs | D10: Calf Raises (Smith) | E10: Smith | F10: lbs | G10: 3 | H10: 20 | I10: 15 | J10: N | K10: =IF($J10="Y","",IF($F10="BW",$I10,$H10*$I10)) -> 300 | L10: =$D10&"|"&$H10 -> Calf Raises (Smith)|20
A11: 46039 | B11: Sat | C11: Legs | D11: Lunges | E11: Bodyweight | F11: BW | G11: 1 | H11: 0 | I11: 10 | J11: N | K11: =IF($J11="Y","",IF($F11="BW",$I11,$H11*$I11)) -> 10 | L11: =$D11&"|"&$H11 -> Lunges|0 | M11: per leg
A12: 46039 | B12: Sat | C12: Legs | D12: Lunges | E12: Bodyweight | F12: BW | G12: 2 | H12: 0 | I12: 10 | J12: N | K12: =IF($J12="Y","",IF($F12="BW",$I12,$H12*$I12)) -> 10 | L12: =$D12&"|"&$H12 -> Lunges|0 | M12: per leg
A13: 46039 | B13: Sat | C13: Legs | D13: Lunges | E13: Bodyweight | F13: BW | G13: 3 | H13: 0 | I13: 10 | J13: N | K13: =IF($J13="Y","",IF($F13="BW",$I13,$H13*$I13)) -> 10 | L13: =$D13&"|"&$H13 -> Lunges|0 | M13: per leg
A14: 46042 | B14: Tue | C14: Push + Pull | D14: Bench Press (DB) | E14: Dumbbell | F14: lbs | G14: 1 | H14: 20 | I14: 10 | J14: N | K14: =IF($J14="Y","",IF($F14="BW",$I14,$H14*$I14)) -> 200 | L14: =$D14&"|"&$H14 -> Bench Press (DB)|20
A15: 46042 | B15: Tue | C15: Push + Pull | D15: Bench Press (DB) | E15: Dumbbell | F15: lbs | G15: 2 | H15: 35 | I15: 10 | J15: N | K15: =IF($J15="Y","",IF($F15="BW",$I15,$H15*$I15)) -> 350 | L15: =$D15&"|"&$H15 -> Bench Press (DB)|35
A16: 46042 | B16: Tue | C16: Push + Pull | D16: Bench Press (DB) | E16: Dumbbell | F16: lbs | G16: 3 | H16: 40 | I16: 10 | J16: N | K16: =IF($J16="Y","",IF($F16="BW",$I16,$H16*$I16)) -> 400 | L16: =$D16&"|"&$H16 -> Bench Press (DB)|40
A17: 46042 | B17: Tue | C17: Push + Pull | D17: Bench Press (DB) | E17: Dumbbell | F17: lbs | G17: 4 | H17: 40 | I17: 10 | J17: N | K17: =IF($J17="Y","",IF($F17="BW",$I17,$H17*$I17)) -> 400 | L17: =$D17&"|"&$H17 -> Bench Press (DB)|40
A18: 46042 | B18: Tue | C18: Push + Pull | D18: Single Arm Lat Pulldown | E18: Cable | F18: kg | G18: 1 | H18: 12.5 | I18: 8 | J18: N | K18: =IF($J18="Y","",IF($F18="BW",$I18,$H18*$I18)) -> 100 | L18: =$D18&"|"&$H18 -> Single Arm Lat Pulldown|12.5
A19: 46042 | B19: Tue | C19: Push + Pull | D19: Single Arm Lat Pulldown | E19: Cable | F19: kg | G19: 2 | H19: 15 | I19: 8 | J19: N | K19: =IF($J19="Y","",IF($F19="BW",$I19,$H19*$I19)) -> 120 | L19: =$D19&"|"&$H19 -> Single Arm Lat Pulldown|15
A20: 46042 | B20: Tue | C20: Push + Pull | D20: Single Arm Lat Pulldown | E20: Cable | F20: kg | G20: 3 | H20: 15 | I20: 8 | J20: N | K20: =IF($J20="Y","",IF($F20="BW",$I20,$H20*$I20)) -> 120 | L20: =$D20&"|"&$H20 -> Single Arm Lat Pulldown|15
A21: 46042 | B21: Tue | C21: Push + Pull | D21: Shoulder Press | E21: Dumbbell | F21: lbs | G21: 1 | H21: 25 | I21: 8 | J21: N | K21: =IF($J21="Y","",IF($F21="BW",$I21,$H21*$I21)) -> 200 | L21: =$D21&"|"&$H21 -> Shoulder Press|25
A22: 46042 | B22: Tue | C22: Push + Pull | D22: Shoulder Press | E22: Dumbbell | F22: lbs | G22: 2 | H22: 30 | I22: 8 | J22: N | K22: =IF($J22="Y","",IF($F22="BW",$I22,$H22*$I22)) -> 240 | L22: =$D22&"|"&$H22 -> Shoulder Press|30
A23: 46042 | B23: Tue | C23: Push + Pull | D23: Bicep Curls (DB) | E23: Dumbbell | F23: lbs | G23: 1 | H23: 25 | I23: 8 | J23: N | K23: =IF($J23="Y","",IF($F23="BW",$I23,$H23*$I23)) -> 200 | L23: =$D23&"|"&$H23 -> Bicep Curls (DB)|25
A24: 46042 | B24: Tue | C24: Push + Pull | D24: Bicep Curls (DB) | E24: Dumbbell | F24: lbs | G24: 2 | H24: 25 | I24: 8 | J24: N | K24: =IF($J24="Y","",IF($F24="BW",$I24,$H24*$I24)) -> 200 | L24: =$D24&"|"&$H24 -> Bicep Curls (DB)|25
A25: 46044 | B25: Thu | C25: Pull + Arms | D25: DB Rows | E25: Dumbbell | F25: lbs | G25: 1 | H25: 15 | I25: 8 | J25: N | K25: =IF($J25="Y","",IF($F25="BW",$I25,$H25*$I25)) -> 120 | L25: =$D25&"|"&$H25 -> DB Rows|15
... A31: 46044 | B31: Thu | C31: Pull + Arms | D31: Bicep Curls (DB) | E31: Dumbbell | F31: lbs | G31: 3 | H31: 30 | I31: 8 | J31: N | K31: =IF($J31="Y","",IF($F31="BW",$I31,$H31*$I31)) -> 240 | L31: =$D31&"|"&$H31 -> Bicep Curls (DB)|30
A32: 46044 | B32: Thu | C32: Pull + Arms | D32: Tricep Ext Overhead | E32: Dumbbell | F32: lbs | G32: 1 | H32: 20 | I32: 8 | J32: N | K32: =IF($J32="Y","",IF($F32="BW",$I32,$H32*$I32)) -> 160 | L32: =$D32&"|"&$H32 -> Tricep Ext Overhead|20 | M32: PR 50
A33: 46044 | B33: Thu | C33: Pull + Arms | D33: Tricep Ext Overhead | E33: Dumbbell | F33: lbs | G33: 2 | H33: 40 | I33: 8 | J33: N | K33: =IF($J33="Y","",IF($F33="BW",$I33,$H33*$I33)) -> 320 | L33: =$D33&"|"&$H33 -> Tricep Ext Overhead|40 | M33: PR 50
A34: 46044 | B34: Thu | C34: Pull + Arms | D34: Tricep Ext Overhead | E34: Dumbbell | F34: lbs | G34: 3 | H34: 50 | I34: 8 | J34: N | K34: =IF($J34="Y","",IF($F34="BW",$I34,$H34*$I34)) -> 400 | L34: =$D34&"|"&$H34 -> Tricep Ext Overhead|50 | M34: PR 50
A35: 46044 | B35: Thu | C35: Pull + Arms | D35: Tricep Ext Overhead | E35: Dumbbell | F35: lbs | G35: 4 | H35: 50 | I35: 8 | J35: N | K35: =IF($J35="Y","",IF($F35="BW",$I35,$H35*$I35)) -> 400 | L35: =$D35&"|"&$H35 -> Tricep Ext Overhead|50 | M35: PR 50
A36: 46045 | B36: Fri | C36: Legs | D36: Squats | E36: Smith | F36: lbs | G36: 1 | H36: 50 | I36: 8 | J36: N | K36: =IF($J36="Y","",IF($F36="BW",$I36,$H36*$I36)) -> 400 | L36: =$D36&"|"&$H36 -> Squats|50
A37: 46045 | B37: Fri | C37: Legs | D37: Squats | E37: Smith | F37: lbs | G37: 2 | H37: 50 | I37: 8 | J37: N | K37: =IF($J37="Y","",IF($F37="BW",$I37,$H37*$I37)) -> 400 | L37: =$D37&"|"&$H37 -> Squats|50
A38: 46045 | B38: Fri | C38: Legs | D38: Squats | E38: Smith | F38: lbs | G38: 3 | H38: 50 | I38: 8 | J38: N | K38: =IF($J38="Y","",IF($F38="BW",$I38,$H38*$I38)) -> 400 | L38: =$D38&"|"&$H38 -> Squats|50
A39: 46045 | B39: Fri | C39: Legs | D39: Lunges | E39: Bodyweight | F39: BW | G39: 1 | H39: 0 | I39: 10 | J39: N | K39: =IF($J39="Y","",IF($F39="BW",$I39,$H39*$I39)) -> 10 | L39: =$D39&"|"&$H39 -> Lunges|0 | M39: per leg
A40: 46045 | B40: Fri | C40: Legs | D40: Lunges | E40: Bodyweight | F40: BW | G40: 2 | H40: 0 | I40: 8 | J40: N | K40: =IF($J40="Y","",IF($F40="BW",$I40,$H40*$I40)) -> 8 | L40: =$D40&"|"&$H40 -> Lunges|0 | M40: per leg
A41: 46045 | B41: Fri | C41: Legs | D41: RDLs | E41: Smith | F41: lbs | G41: 1 | H41: 20 | I41: 8 | J41: N | K41: =IF($J41="Y","",IF($F41="BW",$I41,$H41*$I41)) -> 160 | L41: =$D41&"|"&$H41 -> RDLs|20
A42: 46045 | B42: Fri | C42: Legs | D42: RDLs | E42: Smith | F42: lbs | G42: 2 | H42: 25 | I42: 8 | J42: N | K42: =IF($J42="Y","",IF($F42="BW",$I42,$H42*$I42)) -> 200 | L42: =$D42&"|"&$H42 -> RDLs|25
A43: 46045 | B43: Fri | C43: Legs | D43: RDLs | E43: Smith | F43: lbs | G43: 3 | H43: 30 | I43: 8 | J43: N | K43: =IF($J43="Y","",IF($F43="BW",$I43,$H43*$I43)) -> 240 | L43: =$D43&"|"&$H43 -> RDLs|30
A44: 46045 | B44: Fri | C44: Legs | D44: Calf Raises (Smith) | E44: Smith | F44: lbs | G44: 1 | H44: 25 | I44: 8 | J44: N | K44: =IF($J44="Y","",IF($F44="BW",$I44,$H44*$I44)) -> 200 | L44: =$D44&"|"&$H44 -> Calf Raises (Smith)|25
A45: 46045 | B45: Fri | C45: Legs | D45: Calf Raises (Smith) | E45: Smith | F45: lbs | G45: 2 | H45: 30 | I45: 15 | J45: N | K45: =IF($J45="Y","",IF($F45="BW",$I45,$H45*$I45)) -> 450 | L45: =$D45&"|"&$H45 -> Calf Raises (Smith)|30
...

Sheet Cardio
A1: Date | B1: Day | C1: Modality | D1: Duration | E1: Minutes | F1: Distance | G1: Dist Unit | H1: Calories | I1: Avg HR | J1: Floors | K1: Notes
A2: 46038 | B2: Fri | C2: Treadmill | D2: 20:00 | E2: 20 | K2: Core: plank 30s, bicycle crunches 10/side, russian twists 10, leg raises 5
A3: 46042 | B3: Tue | C3: Run (Peloton) | D3: 30:00 | E3: 30
A4: 46045 | B4: Fri | C4: Elliptical | D4: 10:00 | E4: 10 | K4: Core: 3 rounds
A5: 46047 | B5: Sun | C5: Run | D5: 30:00 | E5: 30 | F5: 2.2 | G5: mi | K5: Core: 3 rounds
A6: 46051 | B6: Thu | C6: Run | D6: 20:00 | E6: 20 | K6: Core: 3 rounds
A7: 46060 | B7: Sat | C7: Run | D7: 20:00 | E7: 20 | K7: First session back after illness
A8: 46062 | B8: Mon | C8: Run | D8: 20:00 | E8: 20
A9: 46063 | B9: Tue | C9: Run | D9: 20:00 | E9: 20
A10: 46074 | B10: Sat | C10: Run | D10: 30:00 | E10: 30
A11: 46117 | B11: Sun | C11: Elliptical | D11: 19:37 | E11: 19.62 | F11: 3.32 | G11: mi | H11: 136 | I11: 118
A12: 46119 | B12: Tue | C12: Elliptical | D12: 30:02 | E12: 30.03 | F12: 6.28 | G12: mi | H12: 245 | I12: 143
A13: 46125 | B13: Mon | C13: Elliptical | D13: 25:16 | E13: 25.27 | F13: 5.14 | G13: mi | H13: 133 | I13: 90 | K13: Core: 3 rounds
A14: 46127 | B14: Wed | C14: Elliptical | D14: 21:13 | E14: 21.22 | F14: 4.57 | G14: mi | H14: 198 | I14: 148
A15: 46129 | B15: Fri | C15: Elliptical | D15: 29:02 | E15: 29.03 | F15: 6.41 | G15: mi | H15: 303 | I15: 147
A16: 46131 | B16: Sun | C16: Elliptical | D16: 20:15 | E16: 20.25 | F16: 4.48 | G16: mi | H16: 168 | I16: 135 | K16: Plus 5 min extra cardio
A17: 46134 | B17: Wed | C17: Elliptical | D17: 15:06 | E17: 15.1 | F17: 2.94 | G17: mi | H17: 120 | I17: 138
A18: 46140 | B18: Tue | C18: Elliptical | D18: 20:03 | E18: 20.05 | F18: 4.61 | G18: mi | H18: 211 | I18: 148
A19: 46140 | B19: Tue | C19: Elliptical | D19: 7:00 | E19: 7
A20: 46142 | B20: Thu | C20: Elliptical | D20: 21:01 | E20: 21.02 | F20: 4.77 | G20: mi | H20: 216 | I20: 152
A21: 46145 | B21: Sun | C21: Rowing | H21: 95
A22: 46145 | B22: Sun | C22: Run (Peloton) | F22: 1 | G22: mi
A23: 46145 | B23: Sun | C23: Walk | F23: 0.21 | G23: mi
A24: 46145 | B24: Sun | C24: Treadmill | D24: 30:00 | E24: 30 | K24: 4 mph / 4% incline - FIRST RUN since knee injury
A25: 46154 | B25: Tue | C25: Elliptical | D25: 25:24 | E25: 25.4 | H25: 259 | I25: 149
A26: 46156 | B26: Thu | C26: Elliptical | D26: 39:26 | E26: 39.43 | F26: 8.02 | G26: mi | H26: 369 | I26: 149 | K26: CARDIO PR - longest session
A27: 46157 | B27: Fri | C27: Treadmill | D27: 32:43 | E27: 32.72 | F27: 2.36 | G27: mi | H27: 224 | I27: 104
A28: 46161 | B28: Tue | C28: Treadmill | D28: 37:24 | E28: 37.4 | F28: 2.73 | G28: mi | H28: 279 | I28: 107 | K28: Core: 3 rounds
A29: 46164 | B29: Fri | C29: Treadmill | D29: 34:13 | E29: 34.22 | F29: 2.58 | G29: mi | H29: 266 | I29: 122
A30: 46165 | B30: Sat | C30: Elliptical | D30: 15:06 | E30: 15.1 | F30: 3.38 | G30: mi | H30: 124 | I30: 143
A31: 46165 | B31: Sat | C31: Elliptical | D31: 14:32 | E31: 14.53 | H31: 112
A32: 46167 | B32: Mon | C32: Elliptical | D32: 20:12 | E32: 20.2 | F32: 4.82 | G32: mi | H32: 177 | I32: 149
A33: 46167 | B33: Mon | C33: Stairs | D33: 14:54 | E33: 14.9 | H33: 133 | J33: 48 | K33: first stair session since knee injury
A34: 46170 | B34: Thu | C34: Elliptical | D34: 17:43 | E34: 17.72 | F34: 3.53 | G34: mi | H34: 127 | I34: 132
A35: 46170 | B35: Thu | C35: Elliptical | D35: 17:05 | E35: 17.08 | F35: 3.84 | G35: mi | H35: 144 | I35: 143
A36: 46171 | B36: Fri | C36: Treadmill | D36: 33:46 | E36: 33.77 | F36: 2.58 | G36: mi | H36: 274
A37: 46172 | B37: Sat | C37: Elliptical | D37: 20:16 | E37: 20.27 | H37: 148 | I37: 131
A38: 46180 | B38: Sun | C38: Outdoor Run | F38: 2 | G38: mi | K38: ADA conference, hotel gym
A39: 46181 | B39: Mon | C39: Outdoor Run | F39: 1.5 | G39: mi | K39: Hotel gym - bench press done, weights not logged
A40: 46182 | B40: Tue | C40: Elliptical | D40: 20:18 | E40: 20.3 | H40: 235 | I40: 152
...

Sheet Progress
A1: Date | B1: Shoulder Press | C1: Single Arm Lat Pulldown | D1: Tricep Ext Overhead | E1: Bench Press (Smith) | F1: Bicep Curls (DB) | G1: Shrugs | H1: Smith Rows | I1: RDLs | J1: Bench Press (DB) | K1: DB Rows | L1: Lateral Raises | M1: Squats | N1: Calf Raises (Smith) | O1: Incline Bench (DB) | P1: Incline Flyes | Q1: Lunges | R1: Tricep Pulldown | S1: Calf Raises (DB) | T1: Assisted Pull-ups | U1: Bicep Curls (Cable) | V1: Bodyweight Squats | W1: Cable Flyes | X1: Chest Press Machine | Y1: Chin-ups | Z1: Dips | AA1: Face Pulls | AB1: Goblet Squats | AC1: Hammer Curls | AD1: Incline Bench (Smith) | AE1: Lat Pulldown Machine | AF1: Shoulder Press Machine | AG1: Standing Cable Press | AH1: Straight Arm Pulldown
A2: 46039 | B2: =IF(_xlfn.MAXIFS(Sets!$H$2:$H$2000,Sets!$A$2:$A$2000,$A2,Sets!$D$2:$D$2000,B$1,Sets!$J$2:$J$2000,"N")=0,"",_xlfn.MAXIFS(Sets!$H$2:$H$2000,Sets!$A$2:$A$2000,$A2,Sets!$D$2:$D$2000,B$1,Sets!$J$2:$J$2000,"N")) | C2: =IF(_xlfn.MAXIFS(Sets!$H$2:$H$2000,Sets!$A$2:$A$2000,$A2,Sets!$D$2:$D$2000,C$1,Sets!$J$2:$J$2000,"N")=0,"",_xlfn.MAXIFS(Sets!$H$2:$H$2000,Sets!$A$2:$A$2000,$A2,Sets!$D$2:$D$2000,C$1,Sets!$J$2:$J$2000,"N")) | D2: =IF(_xlfn.MAXIFS(Sets!$H$2:$H$2000,Sets!$A$2:$A$2000,$A2,Sets!$D$2:$D$2000,D$1,Sets!$J$2:$J$2000,"N")=0,"",_xlfn.MAXIFS(Sets!$H$2:$H$2000,Sets!$A$2:$A$2000,$A2,Sets!$D$2:$D$2000,D$1,Sets!$J$2:$J$2000,"N")) | E2: =IF(_xlfn.MAXIFS(Sets!$H$2:$H$2000,Sets!$A$2:$A$2000,$A2,Sets!$D$2:$D$2000,E$1,Sets!$J$2:$J$2000,"N")=0,"",_xlfn.MAXIFS(Sets!$H$2:$H$2000,Sets!$A$2:$A$2000,$A2,Sets!$D$2:$D$2000,E$1,Sets!$J$2:$J$2000,"N")) | F2: =IF(_xlfn.MAXIFS(Sets!$H$2:$H$2000,Sets!$A$2:$A$2000,$A2,Sets!$D$2:$D$2000,F$1,Sets!$J$2:$J$2000,"N")=0,"",_xlfn.MAXIFS(Sets!$H$2:$H$2000,Sets!$A$2:$A$2000,$A2,Sets!$D$2:$D$2000,F$1,Sets!$J$2:$J$2000,"N")) | G2: =IF(_xlfn.MAXIFS(Sets!$H$2:$H$2000,Sets!$A$2:$A$2000,$A2,Sets!$D$2:$D$2000,G$1,Sets!$J$2:$J$2000,"N")=0,"",_xlfn.MAXIFS(Sets!$H$2:$H$2000,Sets!$A$2:$A$2000,$A2,Sets!$D$2:$D$2000,G$1,Sets!$J$2:$J$2000,"N")) | H2: =IF(_xlfn.MAXIFS(Sets!$H$2:$H$2000,Sets!$A$2:$A$2000,$A2,Sets!$D$2:$D$2000,H$1,Sets!$J$2:$J$2000,"N")=0,"",_xlfn.MAXIFS(Sets!$H$2:$H$2000,Sets!$A$2:$A$2000,$A2,Sets!$D$2:$D$2000,H$1,Sets!$J$2:$J$2000,"N")) | I2: =IF(_xlfn.MAXIFS(Sets!$H$2:$H$2000,Sets!$A$2:$A$2000,$A2,Sets!$D$2:$D$2000,I$1,Sets!$J$2:$J$2000,"N")=0,"",_xlfn.MAXIFS(Sets!$H$2:$H$2000,Sets!$A$2:$A$2000,$A2,Sets!$D$2:$D$2000,I$1,Sets!$J$2:$J$2000,"N")) -> 20 | ... AH2: =IF(_xlfn.MAXIFS(Sets!$H$2:$H$2000,Sets!$A$2:$A$2000,$A2,Sets!$D$2:$D$2000,AH$1,Sets!$J$2:$J$2000,"N")=0,"",_xlfn.MAXIFS(Sets!$H$2:$H$2000,Sets!$A$2:$A$2000,$A2,Sets!$D$2:$D$2000,AH$1,Sets!$J$2:$J$2000,"N"))
A3: 46042 | B3: =IF(_xlfn.MAXIFS(Sets!$H$2:$H$2000,Sets!$A$2:$A$2000,$A3,Sets!$D$2:$D$2000,B$1,Sets!$J$2:$J$2000,"N")=0,"",_xlfn.MAXIFS(Sets!$H$2:$H$2000,Sets!$A$2:$A$2000,$A3,Sets!$D$2:$D$2000,B$1,Sets!$J$2:$J$2000,"N")) -> 30 | C3: =IF(_xlfn.MAXIFS(Sets!$H$2:$H$2000,Sets!$A$2:$A$2000,$A3,Sets!$D$2:$D$2000,C$1,Sets!$J$2:$J$2000,"N")=0,"",_xlfn.MAXIFS(Sets!$H$2:$H$2000,Sets!$A$2:$A$2000,$A3,Sets!$D$2:$D$2000,C$1,Sets!$J$2:$J$2000,"N")) -> 15 | D3: =IF(_xlfn.MAXIFS(Sets!$H$2:$H$2000,Sets!$A$2:$A$2000,$A3,Sets!$D$2:$D$2000,D$1,Sets!$J$2:$J$2000,"N")=0,"",_xlfn.MAXIFS(Sets!$H$2:$H$2000,Sets!$A$2:$A$2000,$A3,Sets!$D$2:$D$2000,D$1,Sets!$J$2:$J$2000,"N")) | E3: =IF(_xlfn.MAXIFS(Sets!$H$2:$H$2000,Sets!$A$2:$A$2000,$A3,Sets!$D$2:$D$2000,E$1,Sets!$J$2:$J$2000,"N")=0,"",_xlfn.MAXIFS(Sets!$H$2:$H$2000,Sets!$A$2:$A$2000,$A3,Sets!$D$2:$D$2000,E$1,Sets!$J$2:$J$2000,"N")) | F3: =IF(_xlfn.MAXIFS(Sets!$H$2:$H$2000,Sets!$A$2:$A$2000,$A3,Sets!$D$2:$D$2000,F$1,Sets!$J$2:$J$2000,"N")=0,"",_xlfn.MAXIFS(Sets!$H$2:$H$2000,Sets!$A$2:$A$2000,$A3,Sets!$D$2:$D$2000,F$1,Sets!$J$2:$J$2000,"N")) -> 25 | G3: =IF(_xlfn.MAXIFS(Sets!$H$2:$H$2000,Sets!$A$2:$A$2000,$A3,Sets!$D$2:$D$2000,G$1,Sets!$J$2:$J$2000,"N")=0,"",_xlfn.MAXIFS(Sets!$H$2:$H$2000,Sets!$A$2:$A$2000,$A3,Sets!$D$2:$D$2000,G$1,Sets!$J$2:$J$2000,"N")) | H3: =IF(_xlfn.MAXIFS(Sets!$H$2:$H$2000,Sets!$A$2:$A$2000,$A3,Sets!$D$2:$D$2000,H$1,Sets!$J$2:$J$2000,"N")=0,"",_xlfn.MAXIFS(Sets!$H$2:$H$2000,Sets!$A$2:$A$2000,$A3,Sets!$D$2:$D$2000,H$1,Sets!$J$2:$J$2000,"N")) | I3: =IF(_xlfn.MAXIFS(Sets!$H$2:$H$2000,Sets!$A$2:$A$2000,$A3,Sets!$D$2:$D$2000,I$1,Sets!$J$2:$J$2000,"N")=0,"",_xlfn.MAXIFS(Sets!$H$2:$H$2000,Sets!$A$2:$A$2000,$A3,Sets!$D$2:$D$2000,I$1,Sets!$J$2:$J$2000,"N")) | ... AH3: =IF(_xlfn.MAXIFS(Sets!$H$2:$H$2000,Sets!$A$2:$A$2000,$A3,Sets!$D$2:$D$2000,AH$1,Sets!$J$2:$J$2000,"N")=0,"",_xlfn.MAXIFS(Sets!$H$2:$H$2000,Sets!$A$2:$A$2000,$A3,Sets!$D$2:$D$2000,AH$1,Sets!$J$2:$J$2000,"N"))
A4: 46044 | B4: =IF(_xlfn.MAXIFS(Sets!$H$2:$H$2000,Sets!$A$2:$A$2000,$A4,Sets!$D$2:$D$2000,B$1,Sets!$J$2:$J$2000,"N")=0,"",_xlfn.MAXIFS(Sets!$H$2:$H$2000,Sets!$A$2:$A$2000,$A4,Sets!$D$2:$D$2000,B$1,Sets!$J$2:$J$2000,"N")) | C4: =IF(_xlfn.MAXIFS(Sets!$H$2:$H$2000,Sets!$A$2:$A$2000,$A4,Sets!$D$2:$D$2000,C$1,Sets!$J$2:$J$2000,"N")=0,"",_xlfn.MAXIFS(Sets!$H$2:$H$2000,Sets!$A$2:$A$2000,$A4,Sets!$D$2:$D$2000,C$1,Sets!$J$2:$J$2000,"N")) | D4: =IF(_xlfn.MAXIFS(Sets!$H$2:$H$2000,Sets!$A$2:$A$2000,$A4,Sets!$D$2:$D$2000,D$1,Sets!$J$2:$J$2000,"N")=0,"",_xlfn.MAXIFS(Sets!$H$2:$H$2000,Sets!$A$2:$A$2000,$A4,Sets!$D$2:$D$2000,D$1,Sets!$J$2:$J$2000,"N")) -> 50 | E4: =IF(_xlfn.MAXIFS(Sets!$H$2:$H$2000,Sets!$A$2:$A$2000,$A4,Sets!$D$2:$D$2000,E$1,Sets!$J$2:$J$2000,"N")=0,"",_xlfn.MAXIFS(Sets!$H$2:$H$2000,Sets!$A$2:$A$2000,$A4,Sets!$D$2:$D$2000,E$1,Sets!$J$2:$J$2000,"N")) | F4: =IF(_xlfn.MAXIFS(Sets!$H$2:$H$2000,Sets!$A$2:$A$2000,$A4,Sets!$D$2:$D$2000,F$1,Sets!$J$2:$J$2000,"N")=0,"",_xlfn.MAXIFS(Sets!$H$2:$H$2000,Sets!$A$2:$A$2000,$A4,Sets!$D$2:$D$2000,F$1,Sets!$J$2:$J$2000,"N")) -> 30 | G4: =IF(_xlfn.MAXIFS(Sets!$H$2:$H$2000,Sets!$A$2:$A$2000,$A4,Sets!$D$2:$D$2000,G$1,Sets!$J$2:$J$2000,"N")=0,"",_xlfn.MAXIFS(Sets!$H$2:$H$2000,Sets!$A$2:$A$2000,$A4,Sets!$D$2:$D$2000,G$1,Sets!$J$2:$J$2000,"N")) | H4: =IF(_xlfn.MAXIFS(Sets!$H$2:$H$2000,Sets!$A$2:$A$2000,$A4,Sets!$D$2:$D$2000,H$1,Sets!$J$2:$J$2000,"N")=0,"",_xlfn.MAXIFS(Sets!$H$2:$H$2000,Sets!$A$2:$A$2000,$A4,Sets!$D$2:$D$2000,H$1,Sets!$J$2:$J$2000,"N")) | I4: =IF(_xlfn.MAXIFS(Sets!$H$2:$H$2000,Sets!$A$2:$A$2000,$A4,Sets!$D$2:$D$2000,I$1,Sets!$J$2:$J$2000,"N")=0,"",_xlfn.MAXIFS(Sets!$H$2:$H$2000,Sets!$A$2:$A$2000,$A4,Sets!$D$2:$D$2000,I$1,Sets!$J$2:$J$2000,"N")) | ... AH4: =IF(_xlfn.MAXIFS(Sets!$H$2:$H$2000,Sets!$A$2:$A$2000,$A4,Sets!$D$2:$D$2000,AH$1,Sets!$J$2:$J$2000,"N")=0,"",_xlfn.MAXIFS(Sets!$H$2:$H$2000,Sets!$A$2:$A$2000,$A4,Sets!$D$2:$D$2000,AH$1,Sets!$J$2:$J$2000,"N"))
A5: 46045 | B5: =IF(_xlfn.MAXIFS(Sets!$H$2:$H$2000,Sets!$A$2:$A$2000,$A5,Sets!$D$2:$D$2000,B$1,Sets!$J$2:$J$2000,"N")=0,"",_xlfn.MAXIFS(Sets!$H$2:$H$2000,Sets!$A$2:$A$2000,$A5,Sets!$D$2:$D$2000,B$1,Sets!$J$2:$J$2000,"N")) | C5: =IF(_xlfn.MAXIFS(Sets!$H$2:$H$2000,Sets!$A$2:$A$2000,$A5,Sets!$D$2:$D$2000,C$1,Sets!$J$2:$J$2000,"N")=0,"",_xlfn.MAXIFS(Sets!$H$2:$H$2000,Sets!$A$2:$A$2000,$A5,Sets!$D$2:$D$2000,C$1,Sets!$J$2:$J$2000,"N")) | D5: =IF(_xlfn.MAXIFS(Sets!$H$2:$H$2000,Sets!$A$2:$A$2000,$A5,Sets!$D$2:$D$2000,D$1,Sets!$J$2:$J$2000,"N")=0,"",_xlfn.MAXIFS(Sets!$H$2:$H$2000,Sets!$A$2:$A$2000,$A5,Sets!$D$2:$D$2000,D$1,Sets!$J$2:$J$2000,"N")) | E5: =IF(_xlfn.MAXIFS(Sets!$H$2:$H$2000,Sets!$A$2:$A$2000,$A5,Sets!$D$2:$D$2000,E$1,Sets!$J$2:$J$2000,"N")=0,"",_xlfn.MAXIFS(Sets!$H$2:$H$2000,Sets!$A$2:$A$2000,$A5,Sets!$D$2:$D$2000,E$1,Sets!$J$2:$J$2000,"N")) | F5: =IF(_xlfn.MAXIFS(Sets!$H$2:$H$2000,Sets!$A$2:$A$2000,$A5,Sets!$D$2:$D$2000,F$1,Sets!$J$2:$J$2000,"N")=0,"",_xlfn.MAXIFS(Sets!$H$2:$H$2000,Sets!$A$2:$A$2000,$A5,Sets!$D$2:$D$2000,F$1,Sets!$J$2:$J$2000,"N")) | G5: =IF(_xlfn.MAXIFS(Sets!$H$2:$H$2000,Sets!$A$2:$A$2000,$A5,Sets!$D$2:$D$2000,G$1,Sets!$J$2:$J$2000,"N")=0,"",_xlfn.MAXIFS(Sets!$H$2:$H$2000,Sets!$A$2:$A$2000,$A5,Sets!$D$2:$D$2000,G$1,Sets!$J$2:$J$2000,"N")) | H5: =IF(_xlfn.MAXIFS(Sets!$H$2:$H$2000,Sets!$A$2:$A$2000,$A5,Sets!$D$2:$D$2000,H$1,Sets!$J$2:$J$2000,"N")=0,"",_xlfn.MAXIFS(Sets!$H$2:$H$2000,Sets!$A$2:$A$2000,$A5,Sets!$D$2:$D$2000,H$1,Sets!$J$2:$J$2000,"N")) | I5: =IF(_xlfn.MAXIFS(Sets!$H$2:$H$2000,Sets!$A$2:$A$2000,$A5,Sets!$D$2:$D$2000,I$1,Sets!$J$2:$J$2000,"N")=0,"",_xlfn.MAXIFS(Sets!$H$2:$H$2000,Sets!$A$2:$A$2000,$A5,Sets!$D$2:$D$2000,I$1,Sets!$J$2:$J$2000,"N")) -> 30 | ... AH5: =IF(_xlfn.MAXIFS(Sets!$H$2:$H$2000,Sets!$A$2:$A$2000,$A5,Sets!$D$2:$D$2000,AH$1,Sets!$J$2:$J$2000,"N")=0,"",_xlfn.MAXIFS(Sets!$H$2:$H$2000,Sets!$A$2:$A$2000,$A5,Sets!$D$2:$D$2000,AH$1,Sets!$J$2:$J$2000,"N"))
A6: 46047 | B6: =IF(_xlfn.MAXIFS(Sets!$H$2:$H$2000,Sets!$A$2:$A$2000,$A6,Sets!$D$2:$D$2000,B$1,Sets!$J$2:$J$2000,"N")=0,"",_xlfn.MAXIFS(Sets!$H$2:$H$2000,Sets!$A$2:$A$2000,$A6,Sets!$D$2:$D$2000,B$1,Sets!$J$2:$J$2000,"N")) | C6: =IF(_xlfn.MAXIFS(Sets!$H$2:$H$2000,Sets!$A$2:$A$2000,$A6,Sets!$D$2:$D$2000,C$1,Sets!$J$2:$J$2000,"N")=0,"",_xlfn.MAXIFS(Sets!$H$2:$H$2000,Sets!$A$2:$A$2000,$A6,Sets!$D$2:$D$2000,C$1,Sets!$J$2:$J$2000,"N")) | D6: =IF(_xlfn.MAXIFS(Sets!$H$2:$H$2000,Sets!$A$2:$A$2000,$A6,Sets!$D$2:$D$2000,D$1,Sets!$J$2:$J$2000,"N")=0,"",_xlfn.MAXIFS(Sets!$H$2:$H$2000,Sets!$A$2:$A$2000,$A6,Sets!$D$2:$D$2000,D$1,Sets!$J$2:$J$2000,"N")) -> 50 | E6: =IF(_xlfn.MAXIFS(Sets!$H$2:$H$2000,Sets!$A$2:$A$2000,$A6,Sets!$D$2:$D$2000,E$1,Sets!$J$2:$J$2000,"N")=0,"",_xlfn.MAXIFS(Sets!$H$2:$H$2000,Sets!$A$2:$A$2000,$A6,Sets!$D$2:$D$2000,E$1,Sets!$J$2:$J$2000,"N")) | F6: =IF(_xlfn.MAXIFS(Sets!$H$2:$H$2000,Sets!$A$2:$A$2000,$A6,Sets!$D$2:$D$2000,F$1,Sets!$J$2:$J$2000,"N")=0,"",_xlfn.MAXIFS(Sets!$H$2:$H$2000,Sets!$A$2:$A$2000,$A6,Sets!$D$2:$D$2000,F$1,Sets!$J$2:$J$2000,"N")) | G6: =IF(_xlfn.MAXIFS(Sets!$H$2:$H$2000,Sets!$A$2:$A$2000,$A6,Sets!$D$2:$D$2000,G$1,Sets!$J$2:$J$2000,"N")=0,"",_xlfn.MAXIFS(Sets!$H$2:$H$2000,Sets!$A$2:$A$2000,$A6,Sets!$D$2:$D$2000,G$1,Sets!$J$2:$J$2000,"N")) | H6: =IF(_xlfn.MAXIFS(Sets!$H$2:$H$2000,Sets!$A$2:$A$2000,$A6,Sets!$D$2:$D$2000,H$1,Sets!$J$2:$J$2000,"N")=0,"",_xlfn.MAXIFS(Sets!$H$2:$H$2000,Sets!$A$2:$A$2000,$A6,Sets!$D$2:$D$2000,H$1,Sets!$J$2:$J$2000,"N")) | I6: =IF(_xlfn.MAXIFS(Sets!$H$2:$H$2000,Sets!$A$2:$A$2000,$A6,Sets!$D$2:$D$2000,I$1,Sets!$J$2:$J$2000,"N")=0,"",_xlfn.MAXIFS(Sets!$H$2:$H$2000,Sets!$A$2:$A$2000,$A6,Sets!$D$2:$D$2000,I$1,Sets!$J$2:$J$2000,"N")) | ... AH6: =IF(_xlfn.MAXIFS(Sets!$H$2:$H$2000,Sets!$A$2:$A$2000,$A6,Sets!$D$2:$D$2000,AH$1,Sets!$J$2:$J$2000,"N")=0,"",_xlfn.MAXIFS(Sets!$H$2:$H$2000,Sets!$A$2:$A$2000,$A6,Sets!$D$2:$D$2000,AH$1,Sets!$J$2:$J$2000,"N"))
A7: 46049 | B7: =IF(_xlfn.MAXIFS(Sets!$H$2:$H$2000,Sets!$A$2:$A$2000,$A7,Sets!$D$2:$D$2000,B$1,Sets!$J$2:$J$2000,"N")=0,"",_xlfn.MAXIFS(Sets!$H$2:$H$2000,Sets!$A$2:$A$2000,$A7,Sets!$D$2:$D$2000,B$1,Sets!$J$2:$J$2000,"N")) -> 35 | C7: =IF(_xlfn.MAXIFS(Sets!$H$2:$H$2000,Sets!$A$2:$A$2000,$A7,Sets!$D$2:$D$2000,C$1,Sets!$J$2:$J$2000,"N")=0,"",_xlfn.MAXIFS(Sets!$H$2:$H$2000,Sets!$A$2:$A$2000,$A7,Sets!$D$2:$D$2000,C$1,Sets!$J$2:$J$2000,"N")) -> 17.5 | D7: =IF(_xlfn.MAXIFS(Sets!$H$2:$H$2000,Sets!$A$2:$A$2000,$A7,Sets!$D$2:$D$2000,D$1,Sets!$J$2:$J$2000,"N")=0,"",_xlfn.MAXIFS(Sets!$H$2:$H$2000,Sets!$A$2:$A$2000,$A7,Sets!$D$2:$D$2000,D$1,Sets!$J$2:$J$2000,"N")) | E7: =IF(_xlfn.MAXIFS(Sets!$H$2:$H$2000,Sets!$A$2:$A$2000,$A7,Sets!$D$2:$D$2000,E$1,Sets!$J$2:$J$2000,"N")=0,"",_xlfn.MAXIFS(Sets!$H$2:$H$2000,Sets!$A$2:$A$2000,$A7,Sets!$D$2:$D$2000,E$1,Sets!$J$2:$J$2000,"N")) | F7: =IF(_xlfn.MAXIFS(Sets!$H$2:$H$2000,Sets!$A$2:$A$2000,$A7,Sets!$D$2:$D$2000,F$1,Sets!$J$2:$J$2000,"N")=0,"",_xlfn.MAXIFS(Sets!$H$2:$H$2000,Sets!$A$2:$A$2000,$A7,Sets!$D$2:$D$2000,F$1,Sets!$J$2:$J$2000,"N")) | G7: =IF(_xlfn.MAXIFS(Sets!$H$2:$H$2000,Sets!$A$2:$A$2000,$A7,Sets!$D$2:$D$2000,G$1,Sets!$J$2:$J$2000,"N")=0,"",_xlfn.MAXIFS(Sets!$H$2:$H$2000,Sets!$A$2:$A$2000,$A7,Sets!$D$2:$D$2000,G$1,Sets!$J$2:$J$2000,"N")) -> 45 | H7: =IF(_xlfn.MAXIFS(Sets!$H$2:$H$2000,Sets!$A$2:$A$2000,$A7,Sets!$D$2:$D$2000,H$1,Sets!$J$2:$J$2000,"N")=0,"",_xlfn.MAXIFS(Sets!$H$2:$H$2000,Sets!$A$2:$A$2000,$A7,Sets!$D$2:$D$2000,H$1,Sets!$J$2:$J$2000,"N")) -> 50 | I7: =IF(_xlfn.MAXIFS(Sets!$H$2:$H$2000,Sets!$A$2:$A$2000,$A7,Sets!$D$2:$D$2000,I$1,Sets!$J$2:$J$2000,"N")=0,"",_xlfn.MAXIFS(Sets!$H$2:$H$2000,Sets!$A$2:$A$2000,$A7,Sets!$D$2:$D$2000,I$1,Sets!$J$2:$J$2000,"N")) | ... AH7: =IF(_xlfn.MAXIFS(Sets!$H$2:$H$2000,Sets!$A$2:$A$2000,$A7,Sets!$D$2:$D$2000,AH$1,Sets!$J$2:$J$2000,"N")=0,"",_xlfn.MAXIFS(Sets!$H$2:$H$2000,Sets!$A$2:$A$2000,$A7,Sets!$D$2:$D$2000,AH$1,Sets!$J$2:$J$2000,"N"))
A8: 46051 | B8: =IF(_xlfn.MAXIFS(Sets!$H$2:$H$2000,Sets!$A$2:$A$2000,$A8,Sets!$D$2:$D$2000,B$1,Sets!$J$2:$J$2000,"N")=0,"",_xlfn.MAXIFS(Sets!$H$2:$H$2000,Sets!$A$2:$A$2000,$A8,Sets!$D$2:$D$2000,B$1,Sets!$J$2:$J$2000,"N")) | C8: =IF(_xlfn.MAXIFS(Sets!$H$2:$H$2000,Sets!$A$2:$A$2000,$A8,Sets!$D$2:$D$2000,C$1,Sets!$J$2:$J$2000,"N")=0,"",_xlfn.MAXIFS(Sets!$H$2:$H$2000,Sets!$A$2:$A$2000,$A8,Sets!$D$2:$D$2000,C$1,Sets!$J$2:$J$2000,"N")) | D8: =IF(_xlfn.MAXIFS(Sets!$H$2:$H$2000,Sets!$A$2:$A$2000,$A8,Sets!$D$2:$D$2000,D$1,Sets!$J$2:$J$2000,"N")=0,"",_xlfn.MAXIFS(Sets!$H$2:$H$2000,Sets!$A$2:$A$2000,$A8,Sets!$D$2:$D$2000,D$1,Sets!$J$2:$J$2000,"N")) | E8: =IF(_xlfn.MAXIFS(Sets!$H$2:$H$2000,Sets!$A$2:$A$2000,$A8,Sets!$D$2:$D$2000,E$1,Sets!$J$2:$J$2000,"N")=0,"",_xlfn.MAXIFS(Sets!$H$2:$H$2000,Sets!$A$2:$A$2000,$A8,Sets!$D$2:$D$2000,E$1,Sets!$J$2:$J$2000,"N")) | F8: =IF(_xlfn.MAXIFS(Sets!$H$2:$H$2000,Sets!$A$2:$A$2000,$A8,Sets!$D$2:$D$2000,F$1,Sets!$J$2:$J$2000,"N")=0,"",_xlfn.MAXIFS(Sets!$H$2:$H$2000,Sets!$A$2:$A$2000,$A8,Sets!$D$2:$D$2000,F$1,Sets!$J$2:$J$2000,"N")) | G8: =IF(_xlfn.MAXIFS(Sets!$H$2:$H$2000,Sets!$A$2:$A$2000,$A8,Sets!$D$2:$D$2000,G$1,Sets!$J$2:$J$2000,"N")=0,"",_xlfn.MAXIFS(Sets!$H$2:$H$2000,Sets!$A$2:$A$2000,$A8,Sets!$D$2:$D$2000,G$1,Sets!$J$2:$J$2000,"N")) | H8: =IF(_xlfn.MAXIFS(Sets!$H$2:$H$2000,Sets!$A$2:$A$2000,$A8,Sets!$D$2:$D$2000,H$1,Sets!$J$2:$J$2000,"N")=0,"",_xlfn.MAXIFS(Sets!$H$2:$H$2000,Sets!$A$2:$A$2000,$A8,Sets!$D$2:$D$2000,H$1,Sets!$J$2:$J$2000,"N")) | I8: =IF(_xlfn.MAXIFS(Sets!$H$2:$H$2000,Sets!$A$2:$A$2000,$A8,Sets!$D$2:$D$2000,I$1,Sets!$J$2:$J$2000,"N")=0,"",_xlfn.MAXIFS(Sets!$H$2:$H$2000,Sets!$A$2:$A$2000,$A8,Sets!$D$2:$D$2000,I$1,Sets!$J$2:$J$2000,"N")) -> 45 | ... AH8: =IF(_xlfn.MAXIFS(Sets!$H$2:$H$2000,Sets!$A$2:$A$2000,$A8,Sets!$D$2:$D$2000,AH$1,Sets!$J$2:$J$2000,"N")=0,"",_xlfn.MAXIFS(Sets!$H$2:$H$2000,Sets!$A$2:$A$2000,$A8,Sets!$D$2:$D$2000,AH$1,Sets!$J$2:$J$2000,"N"))
A9: 46060 | B9: =IF(_xlfn.MAXIFS(Sets!$H$2:$H$2000,Sets!$A$2:$A$2000,$A9,Sets!$D$2:$D$2000,B$1,Sets!$J$2:$J$2000,"N")=0,"",_xlfn.MAXIFS(Sets!$H$2:$H$2000,Sets!$A$2:$A$2000,$A9,Sets!$D$2:$D$2000,B$1,Sets!$J$2:$J$2000,"N")) | C9: =IF(_xlfn.MAXIFS(Sets!$H$2:$H$2000,Sets!$A$2:$A$2000,$A9,Sets!$D$2:$D$2000,C$1,Sets!$J$2:$J$2000,"N")=0,"",_xlfn.MAXIFS(Sets!$H$2:$H$2000,Sets!$A$2:$A$2000,$A9,Sets!$D$2:$D$2000,C$1,Sets!$J$2:$J$2000,"N")) | D9: =IF(_xlfn.MAXIFS(Sets!$H$2:$H$2000,Sets!$A$2:$A$2000,$A9,Sets!$D$2:$D$2000,D$1,Sets!$J$2:$J$2000,"N")=0,"",_xlfn.MAXIFS(Sets!$H$2:$H$2000,Sets!$A$2:$A$2000,$A9,Sets!$D$2:$D$2000,D$1,Sets!$J$2:$J$2000,"N")) | E9: =IF(_xlfn.MAXIFS(Sets!$H$2:$H$2000,Sets!$A$2:$A$2000,$A9,Sets!$D$2:$D$2000,E$1,Sets!$J$2:$J$2000,"N")=0,"",_xlfn.MAXIFS(Sets!$H$2:$H$2000,Sets!$A$2:$A$2000,$A9,Sets!$D$2:$D$2000,E$1,Sets!$J$2:$J$2000,"N")) | F9: =IF(_xlfn.MAXIFS(Sets!$H$2:$H$2000,Sets!$A$2:$A$2000,$A9,Sets!$D$2:$D$2000,F$1,Sets!$J$2:$J$2000,"N")=0,"",_xlfn.MAXIFS(Sets!$H$2:$H$2000,Sets!$A$2:$A$2000,$A9,Sets!$D$2:$D$2000,F$1,Sets!$J$2:$J$2000,"N")) | G9: =IF(_xlfn.MAXIFS(Sets!$H$2:$H$2000,Sets!$A$2:$A$2000,$A9,Sets!$D$2:$D$2000,G$1,Sets!$J$2:$J$2000,"N")=0,"",_xlfn.MAXIFS(Sets!$H$2:$H$2000,Sets!$A$2:$A$2000,$A9,Sets!$D$2:$D$2000,G$1,Sets!$J$2:$J$2000,"N")) | H9: =IF(_xlfn.MAXIFS(Sets!$H$2:$H$2000,Sets!$A$2:$A$2000,$A9,Sets!$D$2:$D$2000,H$1,Sets!$J$2:$J$2000,"N")=0,"",_xlfn.MAXIFS(Sets!$H$2:$H$2000,Sets!$A$2:$A$2000,$A9,Sets!$D$2:$D$2000,H$1,Sets!$J$2:$J$2000,"N")) -> 40 | I9: =IF(_xlfn.MAXIFS(Sets!$H$2:$H$2000,Sets!$A$2:$A$2000,$A9,Sets!$D$2:$D$2000,I$1,Sets!$J$2:$J$2000,"N")=0,"",_xlfn.MAXIFS(Sets!$H$2:$H$2000,Sets!$A$2:$A$2000,$A9,Sets!$D$2:$D$2000,I$1,Sets!$J$2:$J$2000,"N")) | ... AH9: =IF(_xlfn.MAXIFS(Sets!$H$2:$H$2000,Sets!$A$2:$A$2000,$A9,Sets!$D$2:$D$2000,AH$1,Sets!$J$2:$J$2000,"N")=0,"",_xlfn.MAXIFS(Sets!$H$2:$H$2000,Sets!$A$2:$A$2000,$A9,Sets!$D$2:$D$2000,AH$1,Sets!$J$2:$J$2000,"N"))
A10: 46062 | B10: =IF(_xlfn.MAXIFS(Sets!$H$2:$H$2000,Sets!$A$2:$A$2000,$A10,Sets!$D$2:$D$2000,B$1,Sets!$J$2:$J$2000,"N")=0,"",_xlfn.MAXIFS(Sets!$H$2:$H$2000,Sets!$A$2:$A$2000,$A10,Sets!$D$2:$D$2000,B$1,Sets!$J$2:$J$2000,"N")) | C10: =IF(_xlfn.MAXIFS(Sets!$H$2:$H$2000,Sets!$A$2:$A$2000,$A10,Sets!$D$2:$D$2000,C$1,Sets!$J$2:$J$2000,"N")=0,"",_xlfn.MAXIFS(Sets!$H$2:$H$2000,Sets!$A$2:$A$2000,$A10,Sets!$D$2:$D$2000,C$1,Sets!$J$2:$J$2000,"N")) -> 22.5 | D10: =IF(_xlfn.MAXIFS(Sets!$H$2:$H$2000,Sets!$A$2:$A$2000,$A10,Sets!$D$2:$D$2000,D$1,Sets!$J$2:$J$2000,"N")=0,"",_xlfn.MAXIFS(Sets!$H$2:$H$2000,Sets!$A$2:$A$2000,$A10,Sets!$D$2:$D$2000,D$1,Sets!$J$2:$J$2000,"N")) -> 45 | E10: =IF(_xlfn.MAXIFS(Sets!$H$2:$H$2000,Sets!$A$2:$A$2000,$A10,Sets!$D$2:$D$2000,E$1,Sets!$J$2:$J$2000,"N")=0,"",_xlfn.MAXIFS(Sets!$H$2:$H$2000,Sets!$A$2:$A$2000,$A10,Sets!$D$2:$D$2000,E$1,Sets!$J$2:$J$2000,"N")) | F10: =IF(_xlfn.MAXIFS(Sets!$H$2:$H$2000,Sets!$A$2:$A$2000,$A10,Sets!$D$2:$D$2000,F$1,Sets!$J$2:$J$2000,"N")=0,"",_xlfn.MAXIFS(Sets!$H$2:$H$2000,Sets!$A$2:$A$2000,$A10,Sets!$D$2:$D$2000,F$1,Sets!$J$2:$J$2000,"N")) -> 30 | G10: =IF(_xlfn.MAXIFS(Sets!$H$2:$H$2000,Sets!$A$2:$A$2000,$A10,Sets!$D$2:$D$2000,G$1,Sets!$J$2:$J$2000,"N")=0,"",_xlfn.MAXIFS(Sets!$H$2:$H$2000,Sets!$A$2:$A$2000,$A10,Sets!$D$2:$D$2000,G$1,Sets!$J$2:$J$2000,"N")) | H10: =IF(_xlfn.MAXIFS(Sets!$H$2:$H$2000,Sets!$A$2:$A$2000,$A10,Sets!$D$2:$D$2000,H$1,Sets!$J$2:$J$2000,"N")=0,"",_xlfn.MAXIFS(Sets!$H$2:$H$2000,Sets!$A$2:$A$2000,$A10,Sets!$D$2:$D$2000,H$1,Sets!$J$2:$J$2000,"N")) | I10: =IF(_xlfn.MAXIFS(Sets!$H$2:$H$2000,Sets!$A$2:$A$2000,$A10,Sets!$D$2:$D$2000,I$1,Sets!$J$2:$J$2000,"N")=0,"",_xlfn.MAXIFS(Sets!$H$2:$H$2000,Sets!$A$2:$A$2000,$A10,Sets!$D$2:$D$2000,I$1,Sets!$J$2:$J$2000,"N")) | ... AH10: =IF(_xlfn.MAXIFS(Sets!$H$2:$H$2000,Sets!$A$2:$A$2000,$A10,Sets!$D$2:$D$2000,AH$1,Sets!$J$2:$J$2000,"N")=0,"",_xlfn.MAXIFS(Sets!$H$2:$H$2000,Sets!$A$2:$A$2000,$A10,Sets!$D$2:$D$2000,AH$1,Sets!$J$2:$J$2000,"N"))
A11: 46063 | B11: =IF(_xlfn.MAXIFS(Sets!$H$2:$H$2000,Sets!$A$2:$A$2000,$A11,Sets!$D$2:$D$2000,B$1,Sets!$J$2:$J$2000,"N")=0,"",_xlfn.MAXIFS(Sets!$H$2:$H$2000,Sets!$A$2:$A$2000,$A11,Sets!$D$2:$D$2000,B$1,Sets!$J$2:$J$2000,"N")) | C11: =IF(_xlfn.MAXIFS(Sets!$H$2:$H$2000,Sets!$A$2:$A$2000,$A11,Sets!$D$2:$D$2000,C$1,Sets!$J$2:$J$2000,"N")=0,"",_xlfn.MAXIFS(Sets!$H$2:$H$2000,Sets!$A$2:$A$2000,$A11,Sets!$D$2:$D$2000,C$1,Sets!$J$2:$J$2000,"N")) | D11: =IF(_xlfn.MAXIFS(Sets!$H$2:$H$2000,Sets!$A$2:$A$2000,$A11,Sets!$D$2:$D$2000,D$1,Sets!$J$2:$J$2000,"N")=0,"",_xlfn.MAXIFS(Sets!$H$2:$H$2000,Sets!$A$2:$A$2000,$A11,Sets!$D$2:$D$2000,D$1,Sets!$J$2:$J$2000,"N")) | E11: =IF(_xlfn.MAXIFS(Sets!$H$2:$H$2000,Sets!$A$2:$A$2000,$A11,Sets!$D$2:$D$2000,E$1,Sets!$J$2:$J$2000,"N")=0,"",_xlfn.MAXIFS(Sets!$H$2:$H$2000,Sets!$A$2:$A$2000,$A11,Sets!$D$2:$D$2000,E$1,Sets!$J$2:$J$2000,"N")) | F11: =IF(_xlfn.MAXIFS(Sets!$H$2:$H$2000,Sets!$A$2:$A$2000,$A11,Sets!$D$2:$D$2000,F$1,Sets!$J$2:$J$2000,"N")=0,"",_xlfn.MAXIFS(Sets!$H$2:$H$2000,Sets!$A$2:$A$2000,$A11,Sets!$D$2:$D$2000,F$1,Sets!$J$2:$J$2000,"N")) | G11: =IF(_xlfn.MAXIFS(Sets!$H$2:$H$2000,Sets!$A$2:$A$2000,$A11,Sets!$D$2:$D$2000,G$1,Sets!$J$2:$J$2000,"N")=0,"",_xlfn.MAXIFS(Sets!$H$2:$H$2000,Sets!$A$2:$A$2000,$A11,Sets!$D$2:$D$2000,G$1,Sets!$J$2:$J$2000,"N")) | H11: =IF(_xlfn.MAXIFS(Sets!$H$2:$H$2000,Sets!$A$2:$A$2000,$A11,Sets!$D$2:$D$2000,H$1,Sets!$J$2:$J$2000,"N")=0,"",_xlfn.MAXIFS(Sets!$H$2:$H$2000,Sets!$A$2:$A$2000,$A11,Sets!$D$2:$D$2000,H$1,Sets!$J$2:$J$2000,"N")) | I11: =IF(_xlfn.MAXIFS(Sets!$H$2:$H$2000,Sets!$A$2:$A$2000,$A11,Sets!$D$2:$D$2000,I$1,Sets!$J$2:$J$2000,"N")=0,"",_xlfn.MAXIFS(Sets!$H$2:$H$2000,Sets!$A$2:$A$2000,$A11,Sets!$D$2:$D$2000,I$1,Sets!$J$2:$J$2000,"N")) -> 50 | ... AH11: =IF(_xlfn.MAXIFS(Sets!$H$2:$H$2000,Sets!$A$2:$A$2000,$A11,Sets!$D$2:$D$2000,AH$1,Sets!$J$2:$J$2000,"N")=0,"",_xlfn.MAXIFS(Sets!$H$2:$H$2000,Sets!$A$2:$A$2000,$A11,Sets!$D$2:$D$2000,AH$1,Sets!$J$2:$J$2000,"N"))
A12: 46066 | B12: =IF(_xlfn.MAXIFS(Sets!$H$2:$H$2000,Sets!$A$2:$A$2000,$A12,Sets!$D$2:$D$2000,B$1,Sets!$J$2:$J$2000,"N")=0,"",_xlfn.MAXIFS(Sets!$H$2:$H$2000,Sets!$A$2:$A$2000,$A12,Sets!$D$2:$D$2000,B$1,Sets!$J$2:$J$2000,"N")) | C12: =IF(_xlfn.MAXIFS(Sets!$H$2:$H$2000,Sets!$A$2:$A$2000,$A12,Sets!$D$2:$D$2000,C$1,Sets!$J$2:$J$2000,"N")=0,"",_xlfn.MAXIFS(Sets!$H$2:$H$2000,Sets!$A$2:$A$2000,$A12,Sets!$D$2:$D$2000,C$1,Sets!$J$2:$J$2000,"N")) | D12: =IF(_xlfn.MAXIFS(Sets!$H$2:$H$2000,Sets!$A$2:$A$2000,$A12,Sets!$D$2:$D$2000,D$1,Sets!$J$2:$J$2000,"N")=0,"",_xlfn.MAXIFS(Sets!$H$2:$H$2000,Sets!$A$2:$A$2000,$A12,Sets!$D$2:$D$2000,D$1,Sets!$J$2:$J$2000,"N")) | E12: =IF(_xlfn.MAXIFS(Sets!$H$2:$H$2000,Sets!$A$2:$A$2000,$A12,Sets!$D$2:$D$2000,E$1,Sets!$J$2:$J$2000,"N")=0,"",_xlfn.MAXIFS(Sets!$H$2:$H$2000,Sets!$A$2:$A$2000,$A12,Sets!$D$2:$D$2000,E$1,Sets!$J$2:$J$2000,"N")) | F12: =IF(_xlfn.MAXIFS(Sets!$H$2:$H$2000,Sets!$A$2:$A$2000,$A12,Sets!$D$2:$D$2000,F$1,Sets!$J$2:$J$2000,"N")=0,"",_xlfn.MAXIFS(Sets!$H$2:$H$2000,Sets!$A$2:$A$2000,$A12,Sets!$D$2:$D$2000,F$1,Sets!$J$2:$J$2000,"N")) | G12: =IF(_xlfn.MAXIFS(Sets!$H$2:$H$2000,Sets!$A$2:$A$2000,$A12,Sets!$D$2:$D$2000,G$1,Sets!$J$2:$J$2000,"N")=0,"",_xlfn.MAXIFS(Sets!$H$2:$H$2000,Sets!$A$2:$A$2000,$A12,Sets!$D$2:$D$2000,G$1,Sets!$J$2:$J$2000,"N")) | H12: =IF(_xlfn.MAXIFS(Sets!$H$2:$H$2000,Sets!$A$2:$A$2000,$A12,Sets!$D$2:$D$2000,H$1,Sets!$J$2:$J$2000,"N")=0,"",_xlfn.MAXIFS(Sets!$H$2:$H$2000,Sets!$A$2:$A$2000,$A12,Sets!$D$2:$D$2000,H$1,Sets!$J$2:$J$2000,"N")) | I12: =IF(_xlfn.MAXIFS(Sets!$H$2:$H$2000,Sets!$A$2:$A$2000,$A12,Sets!$D$2:$D$2000,I$1,Sets!$J$2:$J$2000,"N")=0,"",_xlfn.MAXIFS(Sets!$H$2:$H$2000,Sets!$A$2:$A$2000,$A12,Sets!$D$2:$D$2000,I$1,Sets!$J$2:$J$2000,"N")) | ... AH12: =IF(_xlfn.MAXIFS(Sets!$H$2:$H$2000,Sets!$A$2:$A$2000,$A12,Sets!$D$2:$D$2000,AH$1,Sets!$J$2:$J$2000,"N")=0,"",_xlfn.MAXIFS(Sets!$H$2:$H$2000,Sets!$A$2:$A$2000,$A12,Sets!$D$2:$D$2000,AH$1,Sets!$J$2:$J$2000,"N"))
A13: 46068 | B13: =IF(_xlfn.MAXIFS(Sets!$H$2:$H$2000,Sets!$A$2:$A$2000,$A13,Sets!$D$2:$D$2000,B$1,Sets!$J$2:$J$2000,"N")=0,"",_xlfn.MAXIFS(Sets!$H$2:$H$2000,Sets!$A$2:$A$2000,$A13,Sets!$D$2:$D$2000,B$1,Sets!$J$2:$J$2000,"N")) | C13: =IF(_xlfn.MAXIFS(Sets!$H$2:$H$2000,Sets!$A$2:$A$2000,$A13,Sets!$D$2:$D$2000,C$1,Sets!$J$2:$J$2000,"N")=0,"",_xlfn.MAXIFS(Sets!$H$2:$H$2000,Sets!$A$2:$A$2000,$A13,Sets!$D$2:$D$2000,C$1,Sets!$J$2:$J$2000,"N")) | D13: =IF(_xlfn.MAXIFS(Sets!$H$2:$H$2000,Sets!$A$2:$A$2000,$A13,Sets!$D$2:$D$2000,D$1,Sets!$J$2:$J$2000,"N")=0,"",_xlfn.MAXIFS(Sets!$H$2:$H$2000,Sets!$A$2:$A$2000,$A13,Sets!$D$2:$D$2000,D$1,Sets!$J$2:$J$2000,"N")) | E13: =IF(_xlfn.MAXIFS(Sets!$H$2:$H$2000,Sets!$A$2:$A$2000,$A13,Sets!$D$2:$D$2000,E$1,Sets!$J$2:$J$2000,"N")=0,"",_xlfn.MAXIFS(Sets!$H$2:$H$2000,Sets!$A$2:$A$2000,$A13,Sets!$D$2:$D$2000,E$1,Sets!$J$2:$J$2000,"N")) | F13: =IF(_xlfn.MAXIFS(Sets!$H$2:$H$2000,Sets!$A$2:$A$2000,$A13,Sets!$D$2:$D$2000,F$1,Sets!$J$2:$J$2000,"N")=0,"",_xlfn.MAXIFS(Sets!$H$2:$H$2000,Sets!$A$2:$A$2000,$A13,Sets!$D$2:$D$2000,F$1,Sets!$J$2:$J$2000,"N")) | G13: =IF(_xlfn.MAXIFS(Sets!$H$2:$H$2000,Sets!$A$2:$A$2000,$A13,Sets!$D$2:$D$2000,G$1,Sets!$J$2:$J$2000,"N")=0,"",_xlfn.MAXIFS(Sets!$H$2:$H$2000,Sets!$A$2:$A$2000,$A13,Sets!$D$2:$D$2000,G$1,Sets!$J$2:$J$2000,"N")) | H13: =IF(_xlfn.MAXIFS(Sets!$H$2:$H$2000,Sets!$A$2:$A$2000,$A13,Sets!$D$2:$D$2000,H$1,Sets!$J$2:$J$2000,"N")=0,"",_xlfn.MAXIFS(Sets!$H$2:$H$2000,Sets!$A$2:$A$2000,$A13,Sets!$D$2:$D$2000,H$1,Sets!$J$2:$J$2000,"N")) | I13: =IF(_xlfn.MAXIFS(Sets!$H$2:$H$2000,Sets!$A$2:$A$2000,$A13,Sets!$D$2:$D$2000,I$1,Sets!$J$2:$J$2000,"N")=0,"",_xlfn.MAXIFS(Sets!$H$2:$H$2000,Sets!$A$2:$A$2000,$A13,Sets!$D$2:$D$2000,I$1,Sets!$J$2:$J$2000,"N")) | ... AH13: =IF(_xlfn.MAXIFS(Sets!$H$2:$H$2000,Sets!$A$2:$A$2000,$A13,Sets!$D$2:$D$2000,AH$1,Sets!$J$2:$J$2000,"N")=0,"",_xlfn.MAXIFS(Sets!$H$2:$H$2000,Sets!$A$2:$A$2000,$A13,Sets!$D$2:$D$2000,AH$1,Sets!$J$2:$J$2000,"N"))
... A52: 46224 | B52: =IF(_xlfn.MAXIFS(Sets!$H$2:$H$2000,Sets!$A$2:$A$2000,$A52,Sets!$D$2:$D$2000,B$1,Sets!$J$2:$J$2000,"N")=0,"",_xlfn.MAXIFS(Sets!$H$2:$H$2000,Sets!$A$2:$A$2000,$A52,Sets!$D$2:$D$2000,B$1,Sets!$J$2:$J$2000,"N")) -> 35 | C52: =IF(_xlfn.MAXIFS(Sets!$H$2:$H$2000,Sets!$A$2:$A$2000,$A52,Sets!$D$2:$D$2000,C$1,Sets!$J$2:$J$2000,"N")=0,"",_xlfn.MAXIFS(Sets!$H$2:$H$2000,Sets!$A$2:$A$2000,$A52,Sets!$D$2:$D$2000,C$1,Sets!$J$2:$J$2000,"N")) | D52: =IF(_xlfn.MAXIFS(Sets!$H$2:$H$2000,Sets!$A$2:$A$2000,$A52,Sets!$D$2:$D$2000,D$1,Sets!$J$2:$J$2000,"N")=0,"",_xlfn.MAXIFS(Sets!$H$2:$H$2000,Sets!$A$2:$A$2000,$A52,Sets!$D$2:$D$2000,D$1,Sets!$J$2:$J$2000,"N")) | E52: =IF(_xlfn.MAXIFS(Sets!$H$2:$H$2000,Sets!$A$2:$A$2000,$A52,Sets!$D$2:$D$2000,E$1,Sets!$J$2:$J$2000,"N")=0,"",_xlfn.MAXIFS(Sets!$H$2:$H$2000,Sets!$A$2:$A$2000,$A52,Sets!$D$2:$D$2000,E$1,Sets!$J$2:$J$2000,"N")) -> 110 | F52: =IF(_xlfn.MAXIFS(Sets!$H$2:$H$2000,Sets!$A$2:$A$2000,$A52,Sets!$D$2:$D$2000,F$1,Sets!$J$2:$J$2000,"N")=0,"",_xlfn.MAXIFS(Sets!$H$2:$H$2000,Sets!$A$2:$A$2000,$A52,Sets!$D$2:$D$2000,F$1,Sets!$J$2:$J$2000,"N")) | G52: =IF(_xlfn.MAXIFS(Sets!$H$2:$H$2000,Sets!$A$2:$A$2000,$A52,Sets!$D$2:$D$2000,G$1,Sets!$J$2:$J$2000,"N")=0,"",_xlfn.MAXIFS(Sets!$H$2:$H$2000,Sets!$A$2:$A$2000,$A52,Sets!$D$2:$D$2000,G$1,Sets!$J$2:$J$2000,"N")) | H52: =IF(_xlfn.MAXIFS(Sets!$H$2:$H$2000,Sets!$A$2:$A$2000,$A52,Sets!$D$2:$D$2000,H$1,Sets!$J$2:$J$2000,"N")=0,"",_xlfn.MAXIFS(Sets!$H$2:$H$2000,Sets!$A$2:$A$2000,$A52,Sets!$D$2:$D$2000,H$1,Sets!$J$2:$J$2000,"N")) | I52: =IF(_xlfn.MAXIFS(Sets!$H$2:$H$2000,Sets!$A$2:$A$2000,$A52,Sets!$D$2:$D$2000,I$1,Sets!$J$2:$J$2000,"N")=0,"",_xlfn.MAXIFS(Sets!$H$2:$H$2000,Sets!$A$2:$A$2000,$A52,Sets!$D$2:$D$2000,I$1,Sets!$J$2:$J$2000,"N")) | ... AH52: =IF(_xlfn.MAXIFS(Sets!$H$2:$H$2000,Sets!$A$2:$A$2000,$A52,Sets!$D$2:$D$2000,AH$1,Sets!$J$2:$J$2000,"N")=0,"",_xlfn.MAXIFS(Sets!$H$2:$H$2000,Sets!$A$2:$A$2000,$A52,Sets!$D$2:$D$2000,AH$1,Sets!$J$2:$J$2000,"N"))

Sheet PR Summary
A1: Exercise | B1: Equipment | C1: Unit | D1: Best Weight | E1: Reps @ Best | F1: Date First Hit | G1: Last Performed | H1: Top Weight Last Session | I1: Working Sets Logged | J1: Total Volume
A2: Shoulder Press | B2: Dumbbell | C2: lbs | D2: =_xlfn.MAXIFS(Sets!$H$2:$H$2000,Sets!$D$2:$D$2000,$A2,Sets!$J$2:$J$2000,"N") -> 35 | E2: =IFERROR(INDEX(Sets!$I$2:$I$2000,MATCH($A2&"|"&$D2,Sets!$L$2:$L$2000,0)),"") -> 8 | F2: =IFERROR(INDEX(Sets!$A$2:$A$2000,MATCH($A2&"|"&$D2,Sets!$L$2:$L$2000,0)),"") -> 46049 | G2: =_xlfn.MAXIFS(Sets!$A$2:$A$2000,Sets!$D$2:$D$2000,$A2) -> 46224 | H2: =_xlfn.MAXIFS(Sets!$H$2:$H$2000,Sets!$D$2:$D$2000,$A2,Sets!$A$2:$A$2000,$G2,Sets!$J$2:$J$2000,"N") -> 35 | I2: =COUNTIFS(Sets!$D$2:$D$2000,$A2,Sets!$J$2:$J$2000,"N") -> 56 | J2: =SUMIFS(Sets!$K$2:$K$2000,Sets!$D$2:$D$2000,$A2,Sets!$J$2:$J$2000,"N") -> 13370
A3: Single Arm Lat Pulldown | B3: Cable | C3: kg | D3: =_xlfn.MAXIFS(Sets!$H$2:$H$2000,Sets!$D$2:$D$2000,$A3,Sets!$J$2:$J$2000,"N") -> 25 | E3: =IFERROR(INDEX(Sets!$I$2:$I$2000,MATCH($A3&"|"&$D3,Sets!$L$2:$L$2000,0)),"") -> 8 | F3: =IFERROR(INDEX(Sets!$A$2:$A$2000,MATCH($A3&"|"&$D3,Sets!$L$2:$L$2000,0)),"") -> 46196 | G3: =_xlfn.MAXIFS(Sets!$A$2:$A$2000,Sets!$D$2:$D$2000,$A3) -> 46222 | H3: =_xlfn.MAXIFS(Sets!$H$2:$H$2000,Sets!$D$2:$D$2000,$A3,Sets!$A$2:$A$2000,$G3,Sets!$J$2:$J$2000,"N") -> 20 | I3: =COUNTIFS(Sets!$D$2:$D$2000,$A3,Sets!$J$2:$J$2000,"N") -> 54 | J3: =SUMIFS(Sets!$K$2:$K$2000,Sets!$D$2:$D$2000,$A3,Sets!$J$2:$J$2000,"N") -> 8700
A4: Tricep Ext Overhead | B4: Dumbbell | C4: lbs | D4: =_xlfn.MAXIFS(Sets!$H$2:$H$2000,Sets!$D$2:$D$2000,$A4,Sets!$J$2:$J$2000,"N") -> 50 | E4: =IFERROR(INDEX(Sets!$I$2:$I$2000,MATCH($A4&"|"&$D4,Sets!$L$2:$L$2000,0)),"") -> 8 | F4: =IFERROR(INDEX(Sets!$A$2:$A$2000,MATCH($A4&"|"&$D4,Sets!$L$2:$L$2000,0)),"") -> 46044 | G4: =_xlfn.MAXIFS(Sets!$A$2:$A$2000,Sets!$D$2:$D$2000,$A4) -> 46219 | H4: =_xlfn.MAXIFS(Sets!$H$2:$H$2000,Sets!$D$2:$D$2000,$A4,Sets!$A$2:$A$2000,$G4,Sets!$J$2:$J$2000,"N") -> 50 | I4: =COUNTIFS(Sets!$D$2:$D$2000,$A4,Sets!$J$2:$J$2000,"N") -> 49 | J4: =SUMIFS(Sets!$K$2:$K$2000,Sets!$D$2:$D$2000,$A4,Sets!$J$2:$J$2000,"N") -> 17320
A5: Bench Press (Smith) | B5: Smith | C5: lbs | D5: =_xlfn.MAXIFS(Sets!$H$2:$H$2000,Sets!$D$2:$D$2000,$A5,Sets!$J$2:$J$2000,"N") -> 110 | E5: =IFERROR(INDEX(Sets!$I$2:$I$2000,MATCH($A5&"|"&$D5,Sets!$L$2:$L$2000,0)),"") -> 8 | F5: =IFERROR(INDEX(Sets!$A$2:$A$2000,MATCH($A5&"|"&$D5,Sets!$L$2:$L$2000,0)),"") -> 46224 | G5: =_xlfn.MAXIFS(Sets!$A$2:$A$2000,Sets!$D$2:$D$2000,$A5) -> 46224 | H5: =_xlfn.MAXIFS(Sets!$H$2:$H$2000,Sets!$D$2:$D$2000,$A5,Sets!$A$2:$A$2000,$G5,Sets!$J$2:$J$2000,"N") -> 110 | I5: =COUNTIFS(Sets!$D$2:$D$2000,$A5,Sets!$J$2:$J$2000,"N") -> 49 | J5: =SUMIFS(Sets!$K$2:$K$2000,Sets!$D$2:$D$2000,$A5,Sets!$J$2:$J$2000,"N") -> 30760
A6: Bicep Curls (DB) | B6: Dumbbell | C6: lbs | D6: =_xlfn.MAXIFS(Sets!$H$2:$H$2000,Sets!$D$2:$D$2000,$A6,Sets!$J$2:$J$2000,"N") -> 30 | E6: =IFERROR(INDEX(Sets!$I$2:$I$2000,MATCH($A6&"|"&$D6,Sets!$L$2:$L$2000,0)),"") -> 8 | F6: =IFERROR(INDEX(Sets!$A$2:$A$2000,MATCH($A6&"|"&$D6,Sets!$L$2:$L$2000,0)),"") -> 46044 | G6: =_xlfn.MAXIFS(Sets!$A$2:$A$2000,Sets!$D$2:$D$2000,$A6) -> 46217 | H6: =_xlfn.MAXIFS(Sets!$H$2:$H$2000,Sets!$D$2:$D$2000,$A6,Sets!$A$2:$A$2000,$G6,Sets!$J$2:$J$2000,"N") -> 30 | I6: =COUNTIFS(Sets!$D$2:$D$2000,$A6,Sets!$J$2:$J$2000,"N") -> 35 | J6: =SUMIFS(Sets!$K$2:$K$2000,Sets!$D$2:$D$2000,$A6,Sets!$J$2:$J$2000,"N") -> 7070
A7: Shrugs | B7: Dumbbell | C7: lbs | D7: =_xlfn.MAXIFS(Sets!$H$2:$H$2000,Sets!$D$2:$D$2000,$A7,Sets!$J$2:$J$2000,"N") -> 50 | E7: =IFERROR(INDEX(Sets!$I$2:$I$2000,MATCH($A7&"|"&$D7,Sets!$L$2:$L$2000,0)),"") -> 8 | F7: =IFERROR(INDEX(Sets!$A$2:$A$2000,MATCH($A7&"|"&$D7,Sets!$L$2:$L$2000,0)),"") -> 46134 | G7: =_xlfn.MAXIFS(Sets!$A$2:$A$2000,Sets!$D$2:$D$2000,$A7) -> 46222 | H7: =_xlfn.MAXIFS(Sets!$H$2:$H$2000,Sets!$D$2:$D$2000,$A7,Sets!$A$2:$A$2000,$G7,Sets!$J$2:$J$2000,"N") -> 50 | I7: =COUNTIFS(Sets!$D$2:$D$2000,$A7,Sets!$J$2:$J$2000,"N") -> 38 | J7: =SUMIFS(Sets!$K$2:$K$2000,Sets!$D$2:$D$2000,$A7,Sets!$J$2:$J$2000,"N") -> 13800
A8: Smith Rows | B8: Smith | C8: lbs | D8: =_xlfn.MAXIFS(Sets!$H$2:$H$2000,Sets!$D$2:$D$2000,$A8,Sets!$J$2:$J$2000,"N") -> 65 | E8: =IFERROR(INDEX(Sets!$I$2:$I$2000,MATCH($A8&"|"&$D8,Sets!$L$2:$L$2000,0)),"") -> 8 | F8: =IFERROR(INDEX(Sets!$A$2:$A$2000,MATCH($A8&"|"&$D8,Sets!$L$2:$L$2000,0)),"") -> 46134 | G8: =_xlfn.MAXIFS(Sets!$A$2:$A$2000,Sets!$D$2:$D$2000,$A8) -> 46222 | H8: =_xlfn.MAXIFS(Sets!$H$2:$H$2000,Sets!$D$2:$D$2000,$A8,Sets!$A$2:$A$2000,$G8,Sets!$J$2:$J$2000,"N") -> 65 | I8: =COUNTIFS(Sets!$D$2:$D$2000,$A8,Sets!$J$2:$J$2000,"N") -> 36 | J8: =SUMIFS(Sets!$K$2:$K$2000,Sets!$D$2:$D$2000,$A8,Sets!$J$2:$J$2000,"N") -> 15160
A9: RDLs | B9: Smith | C9: lbs | D9: =_xlfn.MAXIFS(Sets!$H$2:$H$2000,Sets!$D$2:$D$2000,$A9,Sets!$J$2:$J$2000,"N") -> 55 | E9: =IFERROR(INDEX(Sets!$I$2:$I$2000,MATCH($A9&"|"&$D9,Sets!$L$2:$L$2000,0)),"") -> 8 | F9: =IFERROR(INDEX(Sets!$A$2:$A$2000,MATCH($A9&"|"&$D9,Sets!$L$2:$L$2000,0)),"") -> 46070 | G9: =_xlfn.MAXIFS(Sets!$A$2:$A$2000,Sets!$D$2:$D$2000,$A9) -> 46221 | H9: =_xlfn.MAXIFS(Sets!$H$2:$H$2000,Sets!$D$2:$D$2000,$A9,Sets!$A$2:$A$2000,$G9,Sets!$J$2:$J$2000,"N") -> 55 | I9: =COUNTIFS(Sets!$D$2:$D$2000,$A9,Sets!$J$2:$J$2000,"N") -> 27 | J9: =SUMIFS(Sets!$K$2:$K$2000,Sets!$D$2:$D$2000,$A9,Sets!$J$2:$J$2000,"N") -> 8640
A10: Bench Press (DB) | B10: Dumbbell | C10: lbs | D10: =_xlfn.MAXIFS(Sets!$H$2:$H$2000,Sets!$D$2:$D$2000,$A10,Sets!$J$2:$J$2000,"N") -> 45 | E10: =IFERROR(INDEX(Sets!$I$2:$I$2000,MATCH($A10&"|"&$D10,Sets!$L$2:$L$2000,0)),"") -> 8 | F10: =IFERROR(INDEX(Sets!$A$2:$A$2000,MATCH($A10&"|"&$D10,Sets!$L$2:$L$2000,0)),"") -> 46062 | G10: =_xlfn.MAXIFS(Sets!$A$2:$A$2000,Sets!$D$2:$D$2000,$A10) -> 46080 | H10: =_xlfn.MAXIFS(Sets!$H$2:$H$2000,Sets!$D$2:$D$2000,$A10,Sets!$A$2:$A$2000,$G10,Sets!$J$2:$J$2000,"N") -> 45 | I10: =COUNTIFS(Sets!$D$2:$D$2000,$A10,Sets!$J$2:$J$2000,"N") -> 18 | J10: =SUMIFS(Sets!$K$2:$K$2000,Sets!$D$2:$D$2000,$A10,Sets!$J$2:$J$2000,"N") -> 5670
A11: DB Rows | B11: Dumbbell | C11: lbs | D11: =_xlfn.MAXIFS(Sets!$H$2:$H$2000,Sets!$D$2:$D$2000,$A11,Sets!$J$2:$J$2000,"N") -> 30 | E11: =IFERROR(INDEX(Sets!$I$2:$I$2000,MATCH($A11&"|"&$D11,Sets!$L$2:$L$2000,0)),"") -> 8 | F11: =IFERROR(INDEX(Sets!$A$2:$A$2000,MATCH($A11&"|"&$D11,Sets!$L$2:$L$2000,0)),"") -> 46044 | G11: =_xlfn.MAXIFS(Sets!$A$2:$A$2000,Sets!$D$2:$D$2000,$A11) -> 46156 | H11: =_xlfn.MAXIFS(Sets!$H$2:$H$2000,Sets!$D$2:$D$2000,$A11,Sets!$A$2:$A$2000,$G11,Sets!$J$2:$J$2000,"N") -> 30 | I11: =COUNTIFS(Sets!$D$2:$D$2000,$A11,Sets!$J$2:$J$2000,"N") -> 19 | J11: =SUMIFS(Sets!$K$2:$K$2000,Sets!$D$2:$D$2000,$A11,Sets!$J$2:$J$2000,"N") -> 4144
A12: Lateral Raises | B12: Dumbbell | C12: lbs | D12: =_xlfn.MAXIFS(Sets!$H$2:$H$2000,Sets!$D$2:$D$2000,$A12,Sets!$J$2:$J$2000,"N") -> 10 | E12: =IFERROR(INDEX(Sets!$I$2:$I$2000,MATCH($A12&"|"&$D12,Sets!$L$2:$L$2000,0)),"") -> 12 | F12: =IFERROR(INDEX(Sets!$A$2:$A$2000,MATCH($A12&"|"&$D12,Sets!$L$2:$L$2000,0)),"") -> 46049 | G12: =_xlfn.MAXIFS(Sets!$A$2:$A$2000,Sets!$D$2:$D$2000,$A12) -> 46177 | H12: =_xlfn.MAXIFS(Sets!$H$2:$H$2000,Sets!$D$2:$D$2000,$A12,Sets!$A$2:$A$2000,$G12,Sets!$J$2:$J$2000,"N") -> 10 | I12: =COUNTIFS(Sets!$D$2:$D$2000,$A12,Sets!$J$2:$J$2000,"N") -> 13 | J12: =SUMIFS(Sets!$K$2:$K$2000,Sets!$D$2:$D$2000,$A12,Sets!$J$2:$J$2000,"N") -> 1540
A13: Squats | B13: Smith | C13: lbs | D13: =_xlfn.MAXIFS(Sets!$H$2:$H$2000,Sets!$D$2:$D$2000,$A13,Sets!$J$2:$J$2000,"N") -> 50 | E13: =IFERROR(INDEX(Sets!$I$2:$I$2000,MATCH($A13&"|"&$D13,Sets!$L$2:$L$2000,0)),"") -> 8 | F13: =IFERROR(INDEX(Sets!$A$2:$A$2000,MATCH($A13&"|"&$D13,Sets!$L$2:$L$2000,0)),"") -> 46039 | G13: =_xlfn.MAXIFS(Sets!$A$2:$A$2000,Sets!$D$2:$D$2000,$A13) -> 46070 | H13: =_xlfn.MAXIFS(Sets!$H$2:$H$2000,Sets!$D$2:$D$2000,$A13,Sets!$A$2:$A$2000,$G13,Sets!$J$2:$J$2000,"N") -> 50 | I13: =COUNTIFS(Sets!$D$2:$D$2000,$A13,Sets!$J$2:$J$2000,"N") -> 19 | J13: =SUMIFS(Sets!$K$2:$K$2000,Sets!$D$2:$D$2000,$A13,Sets!$J$2:$J$2000,"N") -> 6680
... A34: Straight Arm Pulldown | B34: Cable | C34: kg | D34: =_xlfn.MAXIFS(Sets!$H$2:$H$2000,Sets!$D$2:$D$2000,$A34,Sets!$J$2:$J$2000,"N") -> 7.5 | E34: =IFERROR(INDEX(Sets!$I$2:$I$2000,MATCH($A34&"|"&$D34,Sets!$L$2:$L$2000,0)),"") -> 8 | F34: =IFERROR(INDEX(Sets!$A$2:$A$2000,MATCH($A34&"|"&$D34,Sets!$L$2:$L$2000,0)),"") -> 46165 | G34: =_xlfn.MAXIFS(Sets!$A$2:$A$2000,Sets!$D$2:$D$2000,$A34) -> 46165 | H34: =_xlfn.MAXIFS(Sets!$H$2:$H$2000,Sets!$D$2:$D$2000,$A34,Sets!$A$2:$A$2000,$G34,Sets!$J$2:$J$2000,"N") -> 7.5 | I34: =COUNTIFS(Sets!$D$2:$D$2000,$A34,Sets!$J$2:$J$2000,"N") -> 4 | J34: =SUMIFS(Sets!$K$2:$K$2000,Sets!$D$2:$D$2000,$A34,Sets!$J$2:$J$2000,"N") -> 160
A36: Notes
A37: Best Weight excludes warmup sets. Cable exercises are in kg; everything else in lbs.
A38: Bodyweight exercises show 0 - track those by reps in the Sets tab instead.
A39: Date First Hit = the earliest session at that weight, so a matched PR keeps its original date.
A40: Total Volume mixes kg and lbs across exercises, so compare it within an exercise, not between them.
A41: Assisted Pull-ups and Dips log ASSIST weight, so a LOWER number is the harder set - 'Best Weight' is inverted there.

Sheet Charts
A1: PROGRESSION CHARTS
A2: Top working weight per session. Gaps are sessions where the lift was not trained.
