Workbook

Sheet README
A1: PELOBROSSSSS - WORKOUT TRACKER
A2: Complete training log, January 16 - July 21, 2026
A4: WHAT'S IN HERE
A5: Sets | B5: One row per set lifted. This is the source of truth - everything else reads from it.
A6: Cardio | B6: One row per cardio bout (elliptical, treadmill, stairs, rowing, runs).
A7: PR Summary | B7: Auto-calculated best weight, date it was first hit, and most recent performance per exercise.
A8: Progress | B8: Top working weight per exercise per session. Feeds the charts.
A9: Charts | B9: Progression lines for the main lifts.
A11: HOW TO ADD A NEW WORKOUT
A12: 1. | B12: Go to the Sets tab and type new rows directly underneath the last one.
A13: 2. | B13: Add the date to column A of the Progress tab (next empty row) and drag the formulas across.
A14: 3. | B14: Log cardio on the Cardio tab. PR Summary updates itself.
B15: All formulas are pre-extended to row 2000, so there is room for roughly two more years of logging.
A17: EXAMPLE ROW (Sets tab) - copy this format
A18: Date | B18: Day | C18: Workout Type | D18: Exercise | E18: Equipment | F18: Unit | G18: Set # | H18: Weight | I18: Reps | J18: Warmup? | K18: Volume | L18: Key | M18: Notes
A19: 46226 | B19: Thu | C19: Push | D19: Bench Press | E19: Smith | F19: lbs | G19: 4 | H19: 110 | I19: 8 | J19: N | K19: (formula) | L19: (formula) | M19: felt strong
A21: CONVENTIONS
A22: Weight | B22: Dumbbell weights are PER HAND. Smith machine and barbell weights are TOTAL.
A23: Unit | B23: lbs for dumbbells / Smith / machines. kg for the cable stack. BW for bodyweight moves.
A24: Warmup? | B24: Y = warmup set (excluded from PR and volume calcs). N = working set.
A25: Reps | B25: Defaults to 8 unless a different number was logged.
A26: Cardio | B26: All indoor cycling is logged as 'Elliptical' per longstanding preference.
A27: Volume | B27: Weight x Reps for working sets. For bodyweight moves it just counts reps.
A29: DATA NOTES
A30: Approximate dates | B30: A handful of February and early-April sessions were reconstructed from a transfer document
B31: and carry an estimated date. They are flagged in the Notes column of the Sets tab.
A32: Missing period | B32: No sessions logged Mar 1 - Apr 4 (knee injury period) or Jun 29 - Jul 8 (vacation).
A33: Partial logs | B33: Two New Orleans hotel-gym sessions (Jun 7-8) have incomplete weight data.
A34: Source | B34: All data transcribed from the coaching conversation log.

Sheet Sets
A1: Date | B1: Day | C1: Workout Type | D1: Exercise | E1: Equipment | F1: Unit | G1: Set # | H1: Weight | I1: Reps | J1: Warmup? | K1: Volume | L1: Key | M1: Notes
A2: 46039 | B2: Sat | C2: Legs | D2: Squats | E2: Smith | F2: lbs | G2: 1 | H2: 50 | I2: 8 | J2: N | K2: =IF($J2="Y","",IF($F2="BW",$I2,$H2*$I2)) | L2: =$D2&"|"&$H2
A3: 46039 | B3: Sat | C3: Legs | D3: Squats | E3: Smith | F3: lbs | G3: 2 | H3: 50 | I3: 8 | J3: N | K3: =IF($J3="Y","",IF($F3="BW",$I3,$H3*$I3)) | L3: =$D3&"|"&$H3
A4: 46039 | B4: Sat | C4: Legs | D4: Squats | E4: Smith | F4: lbs | G4: 3 | H4: 50 | I4: 8 | J4: N | K4: =IF($J4="Y","",IF($F4="BW",$I4,$H4*$I4)) | L4: =$D4&"|"&$H4
A5: 46039 | B5: Sat | C5: Legs | D5: RDLs | E5: Smith | F5: lbs | G5: 1 | H5: 20 | I5: 8 | J5: N | K5: =IF($J5="Y","",IF($F5="BW",$I5,$H5*$I5)) | L5: =$D5&"|"&$H5
A6: 46039 | B6: Sat | C6: Legs | D6: RDLs | E6: Smith | F6: lbs | G6: 2 | H6: 20 | I6: 8 | J6: N | K6: =IF($J6="Y","",IF($F6="BW",$I6,$H6*$I6)) | L6: =$D6&"|"&$H6
A7: 46039 | B7: Sat | C7: Legs | D7: RDLs | E7: Smith | F7: lbs | G7: 3 | H7: 20 | I7: 8 | J7: N | K7: =IF($J7="Y","",IF($F7="BW",$I7,$H7*$I7)) | L7: =$D7&"|"&$H7
A8: 46039 | B8: Sat | C8: Legs | D8: Calf Raises (Smith) | E8: Smith | F8: lbs | G8: 1 | H8: 20 | I8: 15 | J8: N | K8: =IF($J8="Y","",IF($F8="BW",$I8,$H8*$I8)) | L8: =$D8&"|"&$H8
A9: 46039 | B9: Sat | C9: Legs | D9: Calf Raises (Smith) | E9: Smith | F9: lbs | G9: 2 | H9: 20 | I9: 15 | J9: N | K9: =IF($J9="Y","",IF($F9="BW",$I9,$H9*$I9)) | L9: =$D9&"|"&$H9
A10: 46039 | B10: Sat | C10: Legs | D10: Calf Raises (Smith) | E10: Smith | F10: lbs | G10: 3 | H10: 20 | I10: 15 | J10: N | K10: =IF($J10="Y","",IF($F10="BW",$I10,$H10*$I10)) | L10: =$D10&"|"&$H10
A11: 46039 | B11: Sat | C11: Legs | D11: Lunges | E11: Bodyweight | F11: BW | G11: 1 | H11: 0 | I11: 10 | J11: N | K11: =IF($J11="Y","",IF($F11="BW",$I11,$H11*$I11)) | L11: =$D11&"|"&$H11
A12: 46039 | B12: Sat | C12: Legs | D12: Lunges | E12: Bodyweight | F12: BW | G12: 2 | H12: 0 | I12: 10 | J12: N | K12: =IF($J12="Y","",IF($F12="BW",$I12,$H12*$I12)) | L12: =$D12&"|"&$H12
A13: 46039 | B13: Sat | C13: Legs | D13: Lunges | E13: Bodyweight | F13: BW | G13: 3 | H13: 0 | I13: 10 | J13: N | K13: =IF($J13="Y","",IF($F13="BW",$I13,$H13*$I13)) | L13: =$D13&"|"&$H13
... A1026: 46304 | B1026: Fri | C1026: Push + Legs | D1026: RDLs | E1026: Smith | F1026: lbs | G1026: 5 | H1026: 60 | I1026: 8 | J1026: N | K1026: =IF($J1026="Y","",IF($F1026="BW",$I1026,$H1026*$I1026)) | L1026: =$D1026&"|"&$H1026

Sheet Cardio
A1: Date | B1: Day | C1: Modality | D1: Duration | E1: Minutes | F1: Distance | G1: Dist Unit | H1: Calories | I1: Avg HR | J1: Floors | K1: Notes
A2: 46038 | B2: Fri | C2: Treadmill | D2: 20:00 | E2: 20 | K2: Core: plank 30s, bicycle crunches 10/side, russian twists 10, leg raises 5
A3: 46042 | B3: Tue | C3: Run | D3: 30:00 | E3: 30
A4: 46045 | B4: Fri | C4: Elliptical | D4: 10:00 | E4: 10 | K4: Core: 3 rounds
A5: 46047 | B5: Sun | C5: Run | D5: 30:00 | E5: 30 | F5: 2.2 | G5: mi | K5: Core: 3 rounds
A6: 46051 | B6: Thu | C6: Run | D6: 20:00 | E6: 20 | K6: Core: 3 rounds
A7: 46060 | B7: Sat | C7: Run | D7: 20:00 | E7: 20 | K7: First session back after illness
A8: 46062 | B8: Mon | C8: Run | D8: 20:00 | E8: 20
A9: 46063 | B9: Tue | C9: Run | D9: 20:00 | E9: 20
A10: 46074 | B10: Sat | C10: Run | D10: 30:00 | E10: 30
A11: 46117 | B11: Sun | C11: Elliptical | D11: 19:37 | E11: 19.62 | F11: 3.32 | G11: mi | H11: 136 | I11: 118
A12: 46119 | B12: Tue | C12: Elliptical | D12: 30:02 | E12: 30.03 | F12: 6.28 | G12: mi | H12: 245 | I12: 143
A13: 46125 | B13: Mon | C13: Elliptical | D13: 25:16 | E13: 25.27 | F13: 5.14 | G13: mi | H13: 133 | I13: 90 | K13: Core: 3 rounds
A14: 46127 | B14: Wed | C14: Elliptical | D14: 21:13 | E14: 21.22 | F14: 4.57 | G14: mi | H14: 198 | I14: 148
A15: 46129 | B15: Fri | C15: Elliptical | D15: 29:02 | E15: 29.03 | F15: 6.41 | G15: mi | H15: 303 | I15: 147
A16: 46131 | B16: Sun | C16: Elliptical | D16: 20:15 | E16: 20.25 | F16: 4.48 | G16: mi | H16: 168 | I16: 135 | K16: Plus 5 min extra cardio
A17: 46134 | B17: Wed | C17: Elliptical | D17: 15:06 | E17: 15.1 | F17: 2.94 | G17: mi | H17: 120 | I17: 138
A18: 46140 | B18: Tue | C18: Elliptical | D18: 20:03 | E18: 20.05 | F18: 4.61 | G18: mi | H18: 211 | I18: 148
A19: 46140 | B19: Tue | C19: Elliptical | D19: 7:00 | E19: 7
A20: 46142 | B20: Thu | C20: Elliptical | D20: 21:01 | E20: 21.02 | F20: 4.77 | G20: mi | H20: 216 | I20: 152
A21: 46145 | B21: Sun | C21: Rowing | H21: 95
A22: 46145 | B22: Sun | C22: Run | F22: 1 | G22: mi
A23: 46145 | B23: Sun | C23: Treadmill | D23: 30:00 | E23: 30 | K23: 4 mph / 4% incline - FIRST RUN since knee injury
A24: 46145 | B24: Sun | C24: Walk | F24: 0.21 | G24: mi
A25: 46154 | B25: Tue | C25: Elliptical | D25: 25:24 | E25: 25.4 | H25: 259 | I25: 149
A26: 46156 | B26: Thu | C26: Elliptical | D26: 39:26 | E26: 39.43 | F26: 8.02 | G26: mi | H26: 369 | I26: 149 | K26: CARDIO PR - longest session
A27: 46157 | B27: Fri | C27: Treadmill | D27: 32:43 | E27: 32.72 | F27: 2.36 | G27: mi | H27: 224 | I27: 104
A28: 46161 | B28: Tue | C28: Treadmill | D28: 37:24 | E28: 37.4 | F28: 2.73 | G28: mi | H28: 279 | I28: 107 | K28: Core: 3 rounds
A29: 46164 | B29: Fri | C29: Treadmill | D29: 34:13 | E29: 34.22 | F29: 2.58 | G29: mi | H29: 266 | I29: 122
A30: 46165 | B30: Sat | C30: Elliptical | D30: 15:06 | E30: 15.1 | F30: 3.38 | G30: mi | H30: 124 | I30: 143
A31: 46165 | B31: Sat | C31: Elliptical | D31: 14:32 | E31: 14.53 | H31: 112
A32: 46167 | B32: Mon | C32: Elliptical | D32: 20:12 | E32: 20.2 | F32: 4.82 | G32: mi | H32: 177 | I32: 149
A33: 46167 | B33: Mon | C33: Stairs | D33: 14:54 | E33: 14.9 | H33: 133 | K33: first stair session since knee injury
A34: 46170 | B34: Thu | C34: Elliptical | D34: 17:43 | E34: 17.72 | F34: 3.53 | G34: mi | H34: 127 | I34: 132
A35: 46170 | B35: Thu | C35: Elliptical | D35: 17:05 | E35: 17.08 | F35: 3.84 | G35: mi | H35: 144 | I35: 143
A36: 46171 | B36: Fri | C36: Treadmill | D36: 33:46 | E36: 33.77 | F36: 2.58 | G36: mi | H36: 274
A37: 46172 | B37: Sat | C37: Elliptical | D37: 20:16 | E37: 20.27 | H37: 148 | I37: 131
A38: 46180 | B38: Sun | C38: Run | F38: 2 | G38: mi | K38: ADA conference, hotel gym
A39: 46181 | B39: Mon | C39: Run | F39: 1.5 | G39: mi | K39: Hotel gym - bench press done, weights not logged
A40: 46182 | B40: Tue | C40: Elliptical | D40: 20:18 | E40: 20.3 | H40: 235 | I40: 152
...

Sheet Progress
A1: Date | B1: Squats | C1: RDLs | D1: Calf Raises (Smith) | E1: Lunges | F1: Bench Press (DB) | G1: Single Arm Lat Pulldown | H1: Shoulder Press | I1: Bicep Curls (DB) | J1: DB Rows | K1: Tricep Ext Overhead | L1: Incline Flyes | M1: Smith Rows | N1: Lateral Raises | O1: Shrugs | P1: Chest Press Machine | Q1: Lat Pulldown Machine | R1: Shoulder Press Machine | S1: Assisted Pull-ups | T1: Dips | U1: Chin-ups | V1: Bench Press (Smith) | W1: Incline Bench (DB) | X1: Bicep Curls (Cable) | Y1: Face Pulls | Z1: Hammer Curls | AA1: Incline Bench (Smith) | AB1: Standing Cable Press | AC1: Tricep Pulldown | AD1: Straight Arm Pulldown | AE1: Cable Flyes | AF1: Goblet Squats | AG1: Calf Raises (DB) | AH1: Bodyweight Squats | AI1: RDLs (DB) | AJ1: Assisted Neutral Grip Pull-ups | AK1: Assisted Chin-ups | AL1: Hip Abduction | AM1: Hip Adduction | AN1: Assisted Tricep Dips | AO1: Chest-Supported DB Rows | AP1: DB Flyes
A2: 46039 | B2: =IF(_xlfn.MAXIFS(Sets!$H$2:$H$2000,Sets!$A$2:$A$2000,$A2,Sets!$D$2:$D$2000,B$1,Sets!$J$2:$J$2000,"N")=0,"",_xlfn.MAXIFS(Sets!$H$2:$H$2000,Sets!$A$2:$A$2000,$A2,Sets!$D$2:$D$2000,B$1,Sets!$J$2:$J$2000,"N")) | C2: =IF(_xlfn.MAXIFS(Sets!$H$2:$H$2000,Sets!$A$2:$A$2000,$A2,Sets!$D$2:$D$2000,C$1,Sets!$J$2:$J$2000,"N")=0,"",_xlfn.MAXIFS(Sets!$H$2:$H$2000,Sets!$A$2:$A$2000,$A2,Sets!$D$2:$D$2000,C$1,Sets!$J$2:$J$2000,"N")) | D2: =IF(_xlfn.MAXIFS(Sets!$H$2:$H$2000,Sets!$A$2:$A$2000,$A2,Sets!$D$2:$D$2000,D$1,Sets!$J$2:$J$2000,"N")=0,"",_xlfn.MAXIFS(Sets!$H$2:$H$2000,Sets!$A$2:$A$2000,$A2,Sets!$D$2:$D$2000,D$1,Sets!$J$2:$J$2000,"N")) | E2: =IF(_xlfn.MAXIFS(Sets!$H$2:$H$2000,Sets!$A$2:$A$2000,$A2,Sets!$D$2:$D$2000,E$1,Sets!$J$2:$J$2000,"N")=0,"",_xlfn.MAXIFS(Sets!$H$2:$H$2000,Sets!$A$2:$A$2000,$A2,Sets!$D$2:$D$2000,E$1,Sets!$J$2:$J$2000,"N")) | F2: =IF(_xlfn.MAXIFS(Sets!$H$2:$H$2000,Sets!$A$2:$A$2000,$A2,Sets!$D$2:$D$2000,F$1,Sets!$J$2:$J$2000,"N")=0,"",_xlfn.MAXIFS(Sets!$H$2:$H$2000,Sets!$A$2:$A$2000,$A2,Sets!$D$2:$D$2000,F$1,Sets!$J$2:$J$2000,"N")) | G2: =IF(_xlfn.MAXIFS(Sets!$H$2:$H$2000,Sets!$A$2:$A$2000,$A2,Sets!$D$2:$D$2000,G$1,Sets!$J$2:$J$2000,"N")=0,"",_xlfn.MAXIFS(Sets!$H$2:$H$2000,Sets!$A$2:$A$2000,$A2,Sets!$D$2:$D$2000,G$1,Sets!$J$2:$J$2000,"N")) | H2: =IF(_xlfn.MAXIFS(Sets!$H$2:$H$2000,Sets!$A$2:$A$2000,$A2,Sets!$D$2:$D$2000,H$1,Sets!$J$2:$J$2000,"N")=0,"",_xlfn.MAXIFS(Sets!$H$2:$H$2000,Sets!$A$2:$A$2000,$A2,Sets!$D$2:$D$2000,H$1,Sets!$J$2:$J$2000,"N")) | I2: =IF(_xlfn.MAXIFS(Sets!$H$2:$H$2000,Sets!$A$2:$A$2000,$A2,Sets!$D$2:$D$2000,I$1,Sets!$J$2:$J$2000,"N")=0,"",_xlfn.MAXIFS(Sets!$H$2:$H$2000,Sets!$A$2:$A$2000,$A2,Sets!$D$2:$D$2000,I$1,Sets!$J$2:$J$2000,"N")) | ... AP2: =IF(_xlfn.MAXIFS(Sets!$H$2:$H$2000,Sets!$A$2:$A$2000,$A2,Sets!$D$2:$D$2000,AP$1,Sets!$J$2:$J$2000,"N")=0,"",_xlfn.MAXIFS(Sets!$H$2:$H$2000,Sets!$A$2:$A$2000,$A2,Sets!$D$2:$D$2000,AP$1,Sets!$J$2:$J$2000,"N"))
A3: 46042 | B3: =IF(_xlfn.MAXIFS(Sets!$H$2:$H$2000,Sets!$A$2:$A$2000,$A3,Sets!$D$2:$D$2000,B$1,Sets!$J$2:$J$2000,"N")=0,"",_xlfn.MAXIFS(Sets!$H$2:$H$2000,Sets!$A$2:$A$2000,$A3,Sets!$D$2:$D$2000,B$1,Sets!$J$2:$J$2000,"N")) | C3: =IF(_xlfn.MAXIFS(Sets!$H$2:$H$2000,Sets!$A$2:$A$2000,$A3,Sets!$D$2:$D$2000,C$1,Sets!$J$2:$J$2000,"N")=0,"",_xlfn.MAXIFS(Sets!$H$2:$H$2000,Sets!$A$2:$A$2000,$A3,Sets!$D$2:$D$2000,C$1,Sets!$J$2:$J$2000,"N")) | D3: =IF(_xlfn.MAXIFS(Sets!$H$2:$H$2000,Sets!$A$2:$A$2000,$A3,Sets!$D$2:$D$2000,D$1,Sets!$J$2:$J$2000,"N")=0,"",_xlfn.MAXIFS(Sets!$H$2:$H$2000,Sets!$A$2:$A$2000,$A3,Sets!$D$2:$D$2000,D$1,Sets!$J$2:$J$2000,"N")) | E3: =IF(_xlfn.MAXIFS(Sets!$H$2:$H$2000,Sets!$A$2:$A$2000,$A3,Sets!$D$2:$D$2000,E$1,Sets!$J$2:$J$2000,"N")=0,"",_xlfn.MAXIFS(Sets!$H$2:$H$2000,Sets!$A$2:$A$2000,$A3,Sets!$D$2:$D$2000,E$1,Sets!$J$2:$J$2000,"N")) | F3: =IF(_xlfn.MAXIFS(Sets!$H$2:$H$2000,Sets!$A$2:$A$2000,$A3,Sets!$D$2:$D$2000,F$1,Sets!$J$2:$J$2000,"N")=0,"",_xlfn.MAXIFS(Sets!$H$2:$H$2000,Sets!$A$2:$A$2000,$A3,Sets!$D$2:$D$2000,F$1,Sets!$J$2:$J$2000,"N")) | G3: =IF(_xlfn.MAXIFS(Sets!$H$2:$H$2000,Sets!$A$2:$A$2000,$A3,Sets!$D$2:$D$2000,G$1,Sets!$J$2:$J$2000,"N")=0,"",_xlfn.MAXIFS(Sets!$H$2:$H$2000,Sets!$A$2:$A$2000,$A3,Sets!$D$2:$D$2000,G$1,Sets!$J$2:$J$2000,"N")) | H3: =IF(_xlfn.MAXIFS(Sets!$H$2:$H$2000,Sets!$A$2:$A$2000,$A3,Sets!$D$2:$D$2000,H$1,Sets!$J$2:$J$2000,"N")=0,"",_xlfn.MAXIFS(Sets!$H$2:$H$2000,Sets!$A$2:$A$2000,$A3,Sets!$D$2:$D$2000,H$1,Sets!$J$2:$J$2000,"N")) | I3: =IF(_xlfn.MAXIFS(Sets!$H$2:$H$2000,Sets!$A$2:$A$2000,$A3,Sets!$D$2:$D$2000,I$1,Sets!$J$2:$J$2000,"N")=0,"",_xlfn.MAXIFS(Sets!$H$2:$H$2000,Sets!$A$2:$A$2000,$A3,Sets!$D$2:$D$2000,I$1,Sets!$J$2:$J$2000,"N")) | ... AP3: =IF(_xlfn.MAXIFS(Sets!$H$2:$H$2000,Sets!$A$2:$A$2000,$A3,Sets!$D$2:$D$2000,AP$1,Sets!$J$2:$J$2000,"N")=0,"",_xlfn.MAXIFS(Sets!$H$2:$H$2000,Sets!$A$2:$A$2000,$A3,Sets!$D$2:$D$2000,AP$1,Sets!$J$2:$J$2000,"N"))
A4: 46044 | B4: =IF(_xlfn.MAXIFS(Sets!$H$2:$H$2000,Sets!$A$2:$A$2000,$A4,Sets!$D$2:$D$2000,B$1,Sets!$J$2:$J$2000,"N")=0,"",_xlfn.MAXIFS(Sets!$H$2:$H$2000,Sets!$A$2:$A$2000,$A4,Sets!$D$2:$D$2000,B$1,Sets!$J$2:$J$2000,"N")) | C4: =IF(_xlfn.MAXIFS(Sets!$H$2:$H$2000,Sets!$A$2:$A$2000,$A4,Sets!$D$2:$D$2000,C$1,Sets!$J$2:$J$2000,"N")=0,"",_xlfn.MAXIFS(Sets!$H$2:$H$2000,Sets!$A$2:$A$2000,$A4,Sets!$D$2:$D$2000,C$1,Sets!$J$2:$J$2000,"N")) | D4: =IF(_xlfn.MAXIFS(Sets!$H$2:$H$2000,Sets!$A$2:$A$2000,$A4,Sets!$D$2:$D$2000,D$1,Sets!$J$2:$J$2000,"N")=0,"",_xlfn.MAXIFS(Sets!$H$2:$H$2000,Sets!$A$2:$A$2000,$A4,Sets!$D$2:$D$2000,D$1,Sets!$J$2:$J$2000,"N")) | E4: =IF(_xlfn.MAXIFS(Sets!$H$2:$H$2000,Sets!$A$2:$A$2000,$A4,Sets!$D$2:$D$2000,E$1,Sets!$J$2:$J$2000,"N")=0,"",_xlfn.MAXIFS(Sets!$H$2:$H$2000,Sets!$A$2:$A$2000,$A4,Sets!$D$2:$D$2000,E$1,Sets!$J$2:$J$2000,"N")) | F4: =IF(_xlfn.MAXIFS(Sets!$H$2:$H$2000,Sets!$A$2:$A$2000,$A4,Sets!$D$2:$D$2000,F$1,Sets!$J$2:$J$2000,"N")=0,"",_xlfn.MAXIFS(Sets!$H$2:$H$2000,Sets!$A$2:$A$2000,$A4,Sets!$D$2:$D$2000,F$1,Sets!$J$2:$J$2000,"N")) | G4: =IF(_xlfn.MAXIFS(Sets!$H$2:$H$2000,Sets!$A$2:$A$2000,$A4,Sets!$D$2:$D$2000,G$1,Sets!$J$2:$J$2000,"N")=0,"",_xlfn.MAXIFS(Sets!$H$2:$H$2000,Sets!$A$2:$A$2000,$A4,Sets!$D$2:$D$2000,G$1,Sets!$J$2:$J$2000,"N")) | H4: =IF(_xlfn.MAXIFS(Sets!$H$2:$H$2000,Sets!$A$2:$A$2000,$A4,Sets!$D$2:$D$2000,H$1,Sets!$J$2:$J$2000,"N")=0,"",_xlfn.MAXIFS(Sets!$H$2:$H$2000,Sets!$A$2:$A$2000,$A4,Sets!$D$2:$D$2000,H$1,Sets!$J$2:$J$2000,"N")) | I4: =IF(_xlfn.MAXIFS(Sets!$H$2:$H$2000,Sets!$A$2:$A$2000,$A4,Sets!$D$2:$D$2000,I$1,Sets!$J$2:$J$2000,"N")=0,"",_xlfn.MAXIFS(Sets!$H$2:$H$2000,Sets!$A$2:$A$2000,$A4,Sets!$D$2:$D$2000,I$1,Sets!$J$2:$J$2000,"N")) | ... AP4: =IF(_xlfn.MAXIFS(Sets!$H$2:$H$2000,Sets!$A$2:$A$2000,$A4,Sets!$D$2:$D$2000,AP$1,Sets!$J$2:$J$2000,"N")=0,"",_xlfn.MAXIFS(Sets!$H$2:$H$2000,Sets!$A$2:$A$2000,$A4,Sets!$D$2:$D$2000,AP$1,Sets!$J$2:$J$2000,"N"))
A5: 46045 | B5: =IF(_xlfn.MAXIFS(Sets!$H$2:$H$2000,Sets!$A$2:$A$2000,$A5,Sets!$D$2:$D$2000,B$1,Sets!$J$2:$J$2000,"N")=0,"",_xlfn.MAXIFS(Sets!$H$2:$H$2000,Sets!$A$2:$A$2000,$A5,Sets!$D$2:$D$2000,B$1,Sets!$J$2:$J$2000,"N")) | C5: =IF(_xlfn.MAXIFS(Sets!$H$2:$H$2000,Sets!$A$2:$A$2000,$A5,Sets!$D$2:$D$2000,C$1,Sets!$J$2:$J$2000,"N")=0,"",_xlfn.MAXIFS(Sets!$H$2:$H$2000,Sets!$A$2:$A$2000,$A5,Sets!$D$2:$D$2000,C$1,Sets!$J$2:$J$2000,"N")) | D5: =IF(_xlfn.MAXIFS(Sets!$H$2:$H$2000,Sets!$A$2:$A$2000,$A5,Sets!$D$2:$D$2000,D$1,Sets!$J$2:$J$2000,"N")=0,"",_xlfn.MAXIFS(Sets!$H$2:$H$2000,Sets!$A$2:$A$2000,$A5,Sets!$D$2:$D$2000,D$1,Sets!$J$2:$J$2000,"N")) | E5: =IF(_xlfn.MAXIFS(Sets!$H$2:$H$2000,Sets!$A$2:$A$2000,$A5,Sets!$D$2:$D$2000,E$1,Sets!$J$2:$J$2000,"N")=0,"",_xlfn.MAXIFS(Sets!$H$2:$H$2000,Sets!$A$2:$A$2000,$A5,Sets!$D$2:$D$2000,E$1,Sets!$J$2:$J$2000,"N")) | F5: =IF(_xlfn.MAXIFS(Sets!$H$2:$H$2000,Sets!$A$2:$A$2000,$A5,Sets!$D$2:$D$2000,F$1,Sets!$J$2:$J$2000,"N")=0,"",_xlfn.MAXIFS(Sets!$H$2:$H$2000,Sets!$A$2:$A$2000,$A5,Sets!$D$2:$D$2000,F$1,Sets!$J$2:$J$2000,"N")) | G5: =IF(_xlfn.MAXIFS(Sets!$H$2:$H$2000,Sets!$A$2:$A$2000,$A5,Sets!$D$2:$D$2000,G$1,Sets!$J$2:$J$2000,"N")=0,"",_xlfn.MAXIFS(Sets!$H$2:$H$2000,Sets!$A$2:$A$2000,$A5,Sets!$D$2:$D$2000,G$1,Sets!$J$2:$J$2000,"N")) | H5: =IF(_xlfn.MAXIFS(Sets!$H$2:$H$2000,Sets!$A$2:$A$2000,$A5,Sets!$D$2:$D$2000,H$1,Sets!$J$2:$J$2000,"N")=0,"",_xlfn.MAXIFS(Sets!$H$2:$H$2000,Sets!$A$2:$A$2000,$A5,Sets!$D$2:$D$2000,H$1,Sets!$J$2:$J$2000,"N")) | I5: =IF(_xlfn.MAXIFS(Sets!$H$2:$H$2000,Sets!$A$2:$A$2000,$A5,Sets!$D$2:$D$2000,I$1,Sets!$J$2:$J$2000,"N")=0,"",_xlfn.MAXIFS(Sets!$H$2:$H$2000,Sets!$A$2:$A$2000,$A5,Sets!$D$2:$D$2000,I$1,Sets!$J$2:$J$2000,"N")) | ... AP5: =IF(_xlfn.MAXIFS(Sets!$H$2:$H$2000,Sets!$A$2:$A$2000,$A5,Sets!$D$2:$D$2000,AP$1,Sets!$J$2:$J$2000,"N")=0,"",_xlfn.MAXIFS(Sets!$H$2:$H$2000,Sets!$A$2:$A$2000,$A5,Sets!$D$2:$D$2000,AP$1,Sets!$J$2:$J$2000,"N"))
A6: 46047 | B6: =IF(_xlfn.MAXIFS(Sets!$H$2:$H$2000,Sets!$A$2:$A$2000,$A6,Sets!$D$2:$D$2000,B$1,Sets!$J$2:$J$2000,"N")=0,"",_xlfn.MAXIFS(Sets!$H$2:$H$2000,Sets!$A$2:$A$2000,$A6,Sets!$D$2:$D$2000,B$1,Sets!$J$2:$J$2000,"N")) | C6: =IF(_xlfn.MAXIFS(Sets!$H$2:$H$2000,Sets!$A$2:$A$2000,$A6,Sets!$D$2:$D$2000,C$1,Sets!$J$2:$J$2000,"N")=0,"",_xlfn.MAXIFS(Sets!$H$2:$H$2000,Sets!$A$2:$A$2000,$A6,Sets!$D$2:$D$2000,C$1,Sets!$J$2:$J$2000,"N")) | D6: =IF(_xlfn.MAXIFS(Sets!$H$2:$H$2000,Sets!$A$2:$A$2000,$A6,Sets!$D$2:$D$2000,D$1,Sets!$J$2:$J$2000,"N")=0,"",_xlfn.MAXIFS(Sets!$H$2:$H$2000,Sets!$A$2:$A$2000,$A6,Sets!$D$2:$D$2000,D$1,Sets!$J$2:$J$2000,"N")) | E6: =IF(_xlfn.MAXIFS(Sets!$H$2:$H$2000,Sets!$A$2:$A$2000,$A6,Sets!$D$2:$D$2000,E$1,Sets!$J$2:$J$2000,"N")=0,"",_xlfn.MAXIFS(Sets!$H$2:$H$2000,Sets!$A$2:$A$2000,$A6,Sets!$D$2:$D$2000,E$1,Sets!$J$2:$J$2000,"N")) | F6: =IF(_xlfn.MAXIFS(Sets!$H$2:$H$2000,Sets!$A$2:$A$2000,$A6,Sets!$D$2:$D$2000,F$1,Sets!$J$2:$J$2000,"N")=0,"",_xlfn.MAXIFS(Sets!$H$2:$H$2000,Sets!$A$2:$A$2000,$A6,Sets!$D$2:$D$2000,F$1,Sets!$J$2:$J$2000,"N")) | G6: =IF(_xlfn.MAXIFS(Sets!$H$2:$H$2000,Sets!$A$2:$A$2000,$A6,Sets!$D$2:$D$2000,G$1,Sets!$J$2:$J$2000,"N")=0,"",_xlfn.MAXIFS(Sets!$H$2:$H$2000,Sets!$A$2:$A$2000,$A6,Sets!$D$2:$D$2000,G$1,Sets!$J$2:$J$2000,"N")) | H6: =IF(_xlfn.MAXIFS(Sets!$H$2:$H$2000,Sets!$A$2:$A$2000,$A6,Sets!$D$2:$D$2000,H$1,Sets!$J$2:$J$2000,"N")=0,"",_xlfn.MAXIFS(Sets!$H$2:$H$2000,Sets!$A$2:$A$2000,$A6,Sets!$D$2:$D$2000,H$1,Sets!$J$2:$J$2000,"N")) | I6: =IF(_xlfn.MAXIFS(Sets!$H$2:$H$2000,Sets!$A$2:$A$2000,$A6,Sets!$D$2:$D$2000,I$1,Sets!$J$2:$J$2000,"N")=0,"",_xlfn.MAXIFS(Sets!$H$2:$H$2000,Sets!$A$2:$A$2000,$A6,Sets!$D$2:$D$2000,I$1,Sets!$J$2:$J$2000,"N")) | ... AP6: =IF(_xlfn.MAXIFS(Sets!$H$2:$H$2000,Sets!$A$2:$A$2000,$A6,Sets!$D$2:$D$2000,AP$1,Sets!$J$2:$J$2000,"N")=0,"",_xlfn.MAXIFS(Sets!$H$2:$H$2000,Sets!$A$2:$A$2000,$A6,Sets!$D$2:$D$2000,AP$1,Sets!$J$2:$J$2000,"N"))
A7: 46049 | B7: =IF(_xlfn.MAXIFS(Sets!$H$2:$H$2000,Sets!$A$2:$A$2000,$A7,Sets!$D$2:$D$2000,B$1,Sets!$J$2:$J$2000,"N")=0,"",_xlfn.MAXIFS(Sets!$H$2:$H$2000,Sets!$A$2:$A$2000,$A7,Sets!$D$2:$D$2000,B$1,Sets!$J$2:$J$2000,"N")) | C7: =IF(_xlfn.MAXIFS(Sets!$H$2:$H$2000,Sets!$A$2:$A$2000,$A7,Sets!$D$2:$D$2000,C$1,Sets!$J$2:$J$2000,"N")=0,"",_xlfn.MAXIFS(Sets!$H$2:$H$2000,Sets!$A$2:$A$2000,$A7,Sets!$D$2:$D$2000,C$1,Sets!$J$2:$J$2000,"N")) | D7: =IF(_xlfn.MAXIFS(Sets!$H$2:$H$2000,Sets!$A$2:$A$2000,$A7,Sets!$D$2:$D$2000,D$1,Sets!$J$2:$J$2000,"N")=0,"",_xlfn.MAXIFS(Sets!$H$2:$H$2000,Sets!$A$2:$A$2000,$A7,Sets!$D$2:$D$2000,D$1,Sets!$J$2:$J$2000,"N")) | E7: =IF(_xlfn.MAXIFS(Sets!$H$2:$H$2000,Sets!$A$2:$A$2000,$A7,Sets!$D$2:$D$2000,E$1,Sets!$J$2:$J$2000,"N")=0,"",_xlfn.MAXIFS(Sets!$H$2:$H$2000,Sets!$A$2:$A$2000,$A7,Sets!$D$2:$D$2000,E$1,Sets!$J$2:$J$2000,"N")) | F7: =IF(_xlfn.MAXIFS(Sets!$H$2:$H$2000,Sets!$A$2:$A$2000,$A7,Sets!$D$2:$D$2000,F$1,Sets!$J$2:$J$2000,"N")=0,"",_xlfn.MAXIFS(Sets!$H$2:$H$2000,Sets!$A$2:$A$2000,$A7,Sets!$D$2:$D$2000,F$1,Sets!$J$2:$J$2000,"N")) | G7: =IF(_xlfn.MAXIFS(Sets!$H$2:$H$2000,Sets!$A$2:$A$2000,$A7,Sets!$D$2:$D$2000,G$1,Sets!$J$2:$J$2000,"N")=0,"",_xlfn.MAXIFS(Sets!$H$2:$H$2000,Sets!$A$2:$A$2000,$A7,Sets!$D$2:$D$2000,G$1,Sets!$J$2:$J$2000,"N")) | H7: =IF(_xlfn.MAXIFS(Sets!$H$2:$H$2000,Sets!$A$2:$A$2000,$A7,Sets!$D$2:$D$2000,H$1,Sets!$J$2:$J$2000,"N")=0,"",_xlfn.MAXIFS(Sets!$H$2:$H$2000,Sets!$A$2:$A$2000,$A7,Sets!$D$2:$D$2000,H$1,Sets!$J$2:$J$2000,"N")) | I7: =IF(_xlfn.MAXIFS(Sets!$H$2:$H$2000,Sets!$A$2:$A$2000,$A7,Sets!$D$2:$D$2000,I$1,Sets!$J$2:$J$2000,"N")=0,"",_xlfn.MAXIFS(Sets!$H$2:$H$2000,Sets!$A$2:$A$2000,$A7,Sets!$D$2:$D$2000,I$1,Sets!$J$2:$J$2000,"N")) | ... AP7: =IF(_xlfn.MAXIFS(Sets!$H$2:$H$2000,Sets!$A$2:$A$2000,$A7,Sets!$D$2:$D$2000,AP$1,Sets!$J$2:$J$2000,"N")=0,"",_xlfn.MAXIFS(Sets!$H$2:$H$2000,Sets!$A$2:$A$2000,$A7,Sets!$D$2:$D$2000,AP$1,Sets!$J$2:$J$2000,"N"))
A8: 46051 | B8: =IF(_xlfn.MAXIFS(Sets!$H$2:$H$2000,Sets!$A$2:$A$2000,$A8,Sets!$D$2:$D$2000,B$1,Sets!$J$2:$J$2000,"N")=0,"",_xlfn.MAXIFS(Sets!$H$2:$H$2000,Sets!$A$2:$A$2000,$A8,Sets!$D$2:$D$2000,B$1,Sets!$J$2:$J$2000,"N")) | C8: =IF(_xlfn.MAXIFS(Sets!$H$2:$H$2000,Sets!$A$2:$A$2000,$A8,Sets!$D$2:$D$2000,C$1,Sets!$J$2:$J$2000,"N")=0,"",_xlfn.MAXIFS(Sets!$H$2:$H$2000,Sets!$A$2:$A$2000,$A8,Sets!$D$2:$D$2000,C$1,Sets!$J$2:$J$2000,"N")) | D8: =IF(_xlfn.MAXIFS(Sets!$H$2:$H$2000,Sets!$A$2:$A$2000,$A8,Sets!$D$2:$D$2000,D$1,Sets!$J$2:$J$2000,"N")=0,"",_xlfn.MAXIFS(Sets!$H$2:$H$2000,Sets!$A$2:$A$2000,$A8,Sets!$D$2:$D$2000,D$1,Sets!$J$2:$J$2000,"N")) | E8: =IF(_xlfn.MAXIFS(Sets!$H$2:$H$2000,Sets!$A$2:$A$2000,$A8,Sets!$D$2:$D$2000,E$1,Sets!$J$2:$J$2000,"N")=0,"",_xlfn.MAXIFS(Sets!$H$2:$H$2000,Sets!$A$2:$A$2000,$A8,Sets!$D$2:$D$2000,E$1,Sets!$J$2:$J$2000,"N")) | F8: =IF(_xlfn.MAXIFS(Sets!$H$2:$H$2000,Sets!$A$2:$A$2000,$A8,Sets!$D$2:$D$2000,F$1,Sets!$J$2:$J$2000,"N")=0,"",_xlfn.MAXIFS(Sets!$H$2:$H$2000,Sets!$A$2:$A$2000,$A8,Sets!$D$2:$D$2000,F$1,Sets!$J$2:$J$2000,"N")) | G8: =IF(_xlfn.MAXIFS(Sets!$H$2:$H$2000,Sets!$A$2:$A$2000,$A8,Sets!$D$2:$D$2000,G$1,Sets!$J$2:$J$2000,"N")=0,"",_xlfn.MAXIFS(Sets!$H$2:$H$2000,Sets!$A$2:$A$2000,$A8,Sets!$D$2:$D$2000,G$1,Sets!$J$2:$J$2000,"N")) | H8: =IF(_xlfn.MAXIFS(Sets!$H$2:$H$2000,Sets!$A$2:$A$2000,$A8,Sets!$D$2:$D$2000,H$1,Sets!$J$2:$J$2000,"N")=0,"",_xlfn.MAXIFS(Sets!$H$2:$H$2000,Sets!$A$2:$A$2000,$A8,Sets!$D$2:$D$2000,H$1,Sets!$J$2:$J$2000,"N")) | I8: =IF(_xlfn.MAXIFS(Sets!$H$2:$H$2000,Sets!$A$2:$A$2000,$A8,Sets!$D$2:$D$2000,I$1,Sets!$J$2:$J$2000,"N")=0,"",_xlfn.MAXIFS(Sets!$H$2:$H$2000,Sets!$A$2:$A$2000,$A8,Sets!$D$2:$D$2000,I$1,Sets!$J$2:$J$2000,"N")) | ... AP8: =IF(_xlfn.MAXIFS(Sets!$H$2:$H$2000,Sets!$A$2:$A$2000,$A8,Sets!$D$2:$D$2000,AP$1,Sets!$J$2:$J$2000,"N")=0,"",_xlfn.MAXIFS(Sets!$H$2:$H$2000,Sets!$A$2:$A$2000,$A8,Sets!$D$2:$D$2000,AP$1,Sets!$J$2:$J$2000,"N"))
A9: 46060 | B9: =IF(_xlfn.MAXIFS(Sets!$H$2:$H$2000,Sets!$A$2:$A$2000,$A9,Sets!$D$2:$D$2000,B$1,Sets!$J$2:$J$2000,"N")=0,"",_xlfn.MAXIFS(Sets!$H$2:$H$2000,Sets!$A$2:$A$2000,$A9,Sets!$D$2:$D$2000,B$1,Sets!$J$2:$J$2000,"N")) | C9: =IF(_xlfn.MAXIFS(Sets!$H$2:$H$2000,Sets!$A$2:$A$2000,$A9,Sets!$D$2:$D$2000,C$1,Sets!$J$2:$J$2000,"N")=0,"",_xlfn.MAXIFS(Sets!$H$2:$H$2000,Sets!$A$2:$A$2000,$A9,Sets!$D$2:$D$2000,C$1,Sets!$J$2:$J$2000,"N")) | D9: =IF(_xlfn.MAXIFS(Sets!$H$2:$H$2000,Sets!$A$2:$A$2000,$A9,Sets!$D$2:$D$2000,D$1,Sets!$J$2:$J$2000,"N")=0,"",_xlfn.MAXIFS(Sets!$H$2:$H$2000,Sets!$A$2:$A$2000,$A9,Sets!$D$2:$D$2000,D$1,Sets!$J$2:$J$2000,"N")) | E9: =IF(_xlfn.MAXIFS(Sets!$H$2:$H$2000,Sets!$A$2:$A$2000,$A9,Sets!$D$2:$D$2000,E$1,Sets!$J$2:$J$2000,"N")=0,"",_xlfn.MAXIFS(Sets!$H$2:$H$2000,Sets!$A$2:$A$2000,$A9,Sets!$D$2:$D$2000,E$1,Sets!$J$2:$J$2000,"N")) | F9: =IF(_xlfn.MAXIFS(Sets!$H$2:$H$2000,Sets!$A$2:$A$2000,$A9,Sets!$D$2:$D$2000,F$1,Sets!$J$2:$J$2000,"N")=0,"",_xlfn.MAXIFS(Sets!$H$2:$H$2000,Sets!$A$2:$A$2000,$A9,Sets!$D$2:$D$2000,F$1,Sets!$J$2:$J$2000,"N")) | G9: =IF(_xlfn.MAXIFS(Sets!$H$2:$H$2000,Sets!$A$2:$A$2000,$A9,Sets!$D$2:$D$2000,G$1,Sets!$J$2:$J$2000,"N")=0,"",_xlfn.MAXIFS(Sets!$H$2:$H$2000,Sets!$A$2:$A$2000,$A9,Sets!$D$2:$D$2000,G$1,Sets!$J$2:$J$2000,"N")) | H9: =IF(_xlfn.MAXIFS(Sets!$H$2:$H$2000,Sets!$A$2:$A$2000,$A9,Sets!$D$2:$D$2000,H$1,Sets!$J$2:$J$2000,"N")=0,"",_xlfn.MAXIFS(Sets!$H$2:$H$2000,Sets!$A$2:$A$2000,$A9,Sets!$D$2:$D$2000,H$1,Sets!$J$2:$J$2000,"N")) | I9: =IF(_xlfn.MAXIFS(Sets!$H$2:$H$2000,Sets!$A$2:$A$2000,$A9,Sets!$D$2:$D$2000,I$1,Sets!$J$2:$J$2000,"N")=0,"",_xlfn.MAXIFS(Sets!$H$2:$H$2000,Sets!$A$2:$A$2000,$A9,Sets!$D$2:$D$2000,I$1,Sets!$J$2:$J$2000,"N")) | ... AP9: =IF(_xlfn.MAXIFS(Sets!$H$2:$H$2000,Sets!$A$2:$A$2000,$A9,Sets!$D$2:$D$2000,AP$1,Sets!$J$2:$J$2000,"N")=0,"",_xlfn.MAXIFS(Sets!$H$2:$H$2000,Sets!$A$2:$A$2000,$A9,Sets!$D$2:$D$2000,AP$1,Sets!$J$2:$J$2000,"N"))
A10: 46062 | B10: =IF(_xlfn.MAXIFS(Sets!$H$2:$H$2000,Sets!$A$2:$A$2000,$A10,Sets!$D$2:$D$2000,B$1,Sets!$J$2:$J$2000,"N")=0,"",_xlfn.MAXIFS(Sets!$H$2:$H$2000,Sets!$A$2:$A$2000,$A10,Sets!$D$2:$D$2000,B$1,Sets!$J$2:$J$2000,"N")) | C10: =IF(_xlfn.MAXIFS(Sets!$H$2:$H$2000,Sets!$A$2:$A$2000,$A10,Sets!$D$2:$D$2000,C$1,Sets!$J$2:$J$2000,"N")=0,"",_xlfn.MAXIFS(Sets!$H$2:$H$2000,Sets!$A$2:$A$2000,$A10,Sets!$D$2:$D$2000,C$1,Sets!$J$2:$J$2000,"N")) | D10: =IF(_xlfn.MAXIFS(Sets!$H$2:$H$2000,Sets!$A$2:$A$2000,$A10,Sets!$D$2:$D$2000,D$1,Sets!$J$2:$J$2000,"N")=0,"",_xlfn.MAXIFS(Sets!$H$2:$H$2000,Sets!$A$2:$A$2000,$A10,Sets!$D$2:$D$2000,D$1,Sets!$J$2:$J$2000,"N")) | E10: =IF(_xlfn.MAXIFS(Sets!$H$2:$H$2000,Sets!$A$2:$A$2000,$A10,Sets!$D$2:$D$2000,E$1,Sets!$J$2:$J$2000,"N")=0,"",_xlfn.MAXIFS(Sets!$H$2:$H$2000,Sets!$A$2:$A$2000,$A10,Sets!$D$2:$D$2000,E$1,Sets!$J$2:$J$2000,"N")) | F10: =IF(_xlfn.MAXIFS(Sets!$H$2:$H$2000,Sets!$A$2:$A$2000,$A10,Sets!$D$2:$D$2000,F$1,Sets!$J$2:$J$2000,"N")=0,"",_xlfn.MAXIFS(Sets!$H$2:$H$2000,Sets!$A$2:$A$2000,$A10,Sets!$D$2:$D$2000,F$1,Sets!$J$2:$J$2000,"N")) | G10: =IF(_xlfn.MAXIFS(Sets!$H$2:$H$2000,Sets!$A$2:$A$2000,$A10,Sets!$D$2:$D$2000,G$1,Sets!$J$2:$J$2000,"N")=0,"",_xlfn.MAXIFS(Sets!$H$2:$H$2000,Sets!$A$2:$A$2000,$A10,Sets!$D$2:$D$2000,G$1,Sets!$J$2:$J$2000,"N")) | H10: =IF(_xlfn.MAXIFS(Sets!$H$2:$H$2000,Sets!$A$2:$A$2000,$A10,Sets!$D$2:$D$2000,H$1,Sets!$J$2:$J$2000,"N")=0,"",_xlfn.MAXIFS(Sets!$H$2:$H$2000,Sets!$A$2:$A$2000,$A10,Sets!$D$2:$D$2000,H$1,Sets!$J$2:$J$2000,"N")) | I10: =IF(_xlfn.MAXIFS(Sets!$H$2:$H$2000,Sets!$A$2:$A$2000,$A10,Sets!$D$2:$D$2000,I$1,Sets!$J$2:$J$2000,"N")=0,"",_xlfn.MAXIFS(Sets!$H$2:$H$2000,Sets!$A$2:$A$2000,$A10,Sets!$D$2:$D$2000,I$1,Sets!$J$2:$J$2000,"N")) | ... AP10: =IF(_xlfn.MAXIFS(Sets!$H$2:$H$2000,Sets!$A$2:$A$2000,$A10,Sets!$D$2:$D$2000,AP$1,Sets!$J$2:$J$2000,"N")=0,"",_xlfn.MAXIFS(Sets!$H$2:$H$2000,Sets!$A$2:$A$2000,$A10,Sets!$D$2:$D$2000,AP$1,Sets!$J$2:$J$2000,"N"))
A11: 46063 | B11: =IF(_xlfn.MAXIFS(Sets!$H$2:$H$2000,Sets!$A$2:$A$2000,$A11,Sets!$D$2:$D$2000,B$1,Sets!$J$2:$J$2000,"N")=0,"",_xlfn.MAXIFS(Sets!$H$2:$H$2000,Sets!$A$2:$A$2000,$A11,Sets!$D$2:$D$2000,B$1,Sets!$J$2:$J$2000,"N")) | C11: =IF(_xlfn.MAXIFS(Sets!$H$2:$H$2000,Sets!$A$2:$A$2000,$A11,Sets!$D$2:$D$2000,C$1,Sets!$J$2:$J$2000,"N")=0,"",_xlfn.MAXIFS(Sets!$H$2:$H$2000,Sets!$A$2:$A$2000,$A11,Sets!$D$2:$D$2000,C$1,Sets!$J$2:$J$2000,"N")) | D11: =IF(_xlfn.MAXIFS(Sets!$H$2:$H$2000,Sets!$A$2:$A$2000,$A11,Sets!$D$2:$D$2000,D$1,Sets!$J$2:$J$2000,"N")=0,"",_xlfn.MAXIFS(Sets!$H$2:$H$2000,Sets!$A$2:$A$2000,$A11,Sets!$D$2:$D$2000,D$1,Sets!$J$2:$J$2000,"N")) | E11: =IF(_xlfn.MAXIFS(Sets!$H$2:$H$2000,Sets!$A$2:$A$2000,$A11,Sets!$D$2:$D$2000,E$1,Sets!$J$2:$J$2000,"N")=0,"",_xlfn.MAXIFS(Sets!$H$2:$H$2000,Sets!$A$2:$A$2000,$A11,Sets!$D$2:$D$2000,E$1,Sets!$J$2:$J$2000,"N")) | F11: =IF(_xlfn.MAXIFS(Sets!$H$2:$H$2000,Sets!$A$2:$A$2000,$A11,Sets!$D$2:$D$2000,F$1,Sets!$J$2:$J$2000,"N")=0,"",_xlfn.MAXIFS(Sets!$H$2:$H$2000,Sets!$A$2:$A$2000,$A11,Sets!$D$2:$D$2000,F$1,Sets!$J$2:$J$2000,"N")) | G11: =IF(_xlfn.MAXIFS(Sets!$H$2:$H$2000,Sets!$A$2:$A$2000,$A11,Sets!$D$2:$D$2000,G$1,Sets!$J$2:$J$2000,"N")=0,"",_xlfn.MAXIFS(Sets!$H$2:$H$2000,Sets!$A$2:$A$2000,$A11,Sets!$D$2:$D$2000,G$1,Sets!$J$2:$J$2000,"N")) | H11: =IF(_xlfn.MAXIFS(Sets!$H$2:$H$2000,Sets!$A$2:$A$2000,$A11,Sets!$D$2:$D$2000,H$1,Sets!$J$2:$J$2000,"N")=0,"",_xlfn.MAXIFS(Sets!$H$2:$H$2000,Sets!$A$2:$A$2000,$A11,Sets!$D$2:$D$2000,H$1,Sets!$J$2:$J$2000,"N")) | I11: =IF(_xlfn.MAXIFS(Sets!$H$2:$H$2000,Sets!$A$2:$A$2000,$A11,Sets!$D$2:$D$2000,I$1,Sets!$J$2:$J$2000,"N")=0,"",_xlfn.MAXIFS(Sets!$H$2:$H$2000,Sets!$A$2:$A$2000,$A11,Sets!$D$2:$D$2000,I$1,Sets!$J$2:$J$2000,"N")) | ... AP11: =IF(_xlfn.MAXIFS(Sets!$H$2:$H$2000,Sets!$A$2:$A$2000,$A11,Sets!$D$2:$D$2000,AP$1,Sets!$J$2:$J$2000,"N")=0,"",_xlfn.MAXIFS(Sets!$H$2:$H$2000,Sets!$A$2:$A$2000,$A11,Sets!$D$2:$D$2000,AP$1,Sets!$J$2:$J$2000,"N"))
A12: 46066 | B12: =IF(_xlfn.MAXIFS(Sets!$H$2:$H$2000,Sets!$A$2:$A$2000,$A12,Sets!$D$2:$D$2000,B$1,Sets!$J$2:$J$2000,"N")=0,"",_xlfn.MAXIFS(Sets!$H$2:$H$2000,Sets!$A$2:$A$2000,$A12,Sets!$D$2:$D$2000,B$1,Sets!$J$2:$J$2000,"N")) | C12: =IF(_xlfn.MAXIFS(Sets!$H$2:$H$2000,Sets!$A$2:$A$2000,$A12,Sets!$D$2:$D$2000,C$1,Sets!$J$2:$J$2000,"N")=0,"",_xlfn.MAXIFS(Sets!$H$2:$H$2000,Sets!$A$2:$A$2000,$A12,Sets!$D$2:$D$2000,C$1,Sets!$J$2:$J$2000,"N")) | D12: =IF(_xlfn.MAXIFS(Sets!$H$2:$H$2000,Sets!$A$2:$A$2000,$A12,Sets!$D$2:$D$2000,D$1,Sets!$J$2:$J$2000,"N")=0,"",_xlfn.MAXIFS(Sets!$H$2:$H$2000,Sets!$A$2:$A$2000,$A12,Sets!$D$2:$D$2000,D$1,Sets!$J$2:$J$2000,"N")) | E12: =IF(_xlfn.MAXIFS(Sets!$H$2:$H$2000,Sets!$A$2:$A$2000,$A12,Sets!$D$2:$D$2000,E$1,Sets!$J$2:$J$2000,"N")=0,"",_xlfn.MAXIFS(Sets!$H$2:$H$2000,Sets!$A$2:$A$2000,$A12,Sets!$D$2:$D$2000,E$1,Sets!$J$2:$J$2000,"N")) | F12: =IF(_xlfn.MAXIFS(Sets!$H$2:$H$2000,Sets!$A$2:$A$2000,$A12,Sets!$D$2:$D$2000,F$1,Sets!$J$2:$J$2000,"N")=0,"",_xlfn.MAXIFS(Sets!$H$2:$H$2000,Sets!$A$2:$A$2000,$A12,Sets!$D$2:$D$2000,F$1,Sets!$J$2:$J$2000,"N")) | G12: =IF(_xlfn.MAXIFS(Sets!$H$2:$H$2000,Sets!$A$2:$A$2000,$A12,Sets!$D$2:$D$2000,G$1,Sets!$J$2:$J$2000,"N")=0,"",_xlfn.MAXIFS(Sets!$H$2:$H$2000,Sets!$A$2:$A$2000,$A12,Sets!$D$2:$D$2000,G$1,Sets!$J$2:$J$2000,"N")) | H12: =IF(_xlfn.MAXIFS(Sets!$H$2:$H$2000,Sets!$A$2:$A$2000,$A12,Sets!$D$2:$D$2000,H$1,Sets!$J$2:$J$2000,"N")=0,"",_xlfn.MAXIFS(Sets!$H$2:$H$2000,Sets!$A$2:$A$2000,$A12,Sets!$D$2:$D$2000,H$1,Sets!$J$2:$J$2000,"N")) | I12: =IF(_xlfn.MAXIFS(Sets!$H$2:$H$2000,Sets!$A$2:$A$2000,$A12,Sets!$D$2:$D$2000,I$1,Sets!$J$2:$J$2000,"N")=0,"",_xlfn.MAXIFS(Sets!$H$2:$H$2000,Sets!$A$2:$A$2000,$A12,Sets!$D$2:$D$2000,I$1,Sets!$J$2:$J$2000,"N")) | ... AP12: =IF(_xlfn.MAXIFS(Sets!$H$2:$H$2000,Sets!$A$2:$A$2000,$A12,Sets!$D$2:$D$2000,AP$1,Sets!$J$2:$J$2000,"N")=0,"",_xlfn.MAXIFS(Sets!$H$2:$H$2000,Sets!$A$2:$A$2000,$A12,Sets!$D$2:$D$2000,AP$1,Sets!$J$2:$J$2000,"N"))
A13: 46068 | B13: =IF(_xlfn.MAXIFS(Sets!$H$2:$H$2000,Sets!$A$2:$A$2000,$A13,Sets!$D$2:$D$2000,B$1,Sets!$J$2:$J$2000,"N")=0,"",_xlfn.MAXIFS(Sets!$H$2:$H$2000,Sets!$A$2:$A$2000,$A13,Sets!$D$2:$D$2000,B$1,Sets!$J$2:$J$2000,"N")) | C13: =IF(_xlfn.MAXIFS(Sets!$H$2:$H$2000,Sets!$A$2:$A$2000,$A13,Sets!$D$2:$D$2000,C$1,Sets!$J$2:$J$2000,"N")=0,"",_xlfn.MAXIFS(Sets!$H$2:$H$2000,Sets!$A$2:$A$2000,$A13,Sets!$D$2:$D$2000,C$1,Sets!$J$2:$J$2000,"N")) | D13: =IF(_xlfn.MAXIFS(Sets!$H$2:$H$2000,Sets!$A$2:$A$2000,$A13,Sets!$D$2:$D$2000,D$1,Sets!$J$2:$J$2000,"N")=0,"",_xlfn.MAXIFS(Sets!$H$2:$H$2000,Sets!$A$2:$A$2000,$A13,Sets!$D$2:$D$2000,D$1,Sets!$J$2:$J$2000,"N")) | E13: =IF(_xlfn.MAXIFS(Sets!$H$2:$H$2000,Sets!$A$2:$A$2000,$A13,Sets!$D$2:$D$2000,E$1,Sets!$J$2:$J$2000,"N")=0,"",_xlfn.MAXIFS(Sets!$H$2:$H$2000,Sets!$A$2:$A$2000,$A13,Sets!$D$2:$D$2000,E$1,Sets!$J$2:$J$2000,"N")) | F13: =IF(_xlfn.MAXIFS(Sets!$H$2:$H$2000,Sets!$A$2:$A$2000,$A13,Sets!$D$2:$D$2000,F$1,Sets!$J$2:$J$2000,"N")=0,"",_xlfn.MAXIFS(Sets!$H$2:$H$2000,Sets!$A$2:$A$2000,$A13,Sets!$D$2:$D$2000,F$1,Sets!$J$2:$J$2000,"N")) | G13: =IF(_xlfn.MAXIFS(Sets!$H$2:$H$2000,Sets!$A$2:$A$2000,$A13,Sets!$D$2:$D$2000,G$1,Sets!$J$2:$J$2000,"N")=0,"",_xlfn.MAXIFS(Sets!$H$2:$H$2000,Sets!$A$2:$A$2000,$A13,Sets!$D$2:$D$2000,G$1,Sets!$J$2:$J$2000,"N")) | H13: =IF(_xlfn.MAXIFS(Sets!$H$2:$H$2000,Sets!$A$2:$A$2000,$A13,Sets!$D$2:$D$2000,H$1,Sets!$J$2:$J$2000,"N")=0,"",_xlfn.MAXIFS(Sets!$H$2:$H$2000,Sets!$A$2:$A$2000,$A13,Sets!$D$2:$D$2000,H$1,Sets!$J$2:$J$2000,"N")) | I13: =IF(_xlfn.MAXIFS(Sets!$H$2:$H$2000,Sets!$A$2:$A$2000,$A13,Sets!$D$2:$D$2000,I$1,Sets!$J$2:$J$2000,"N")=0,"",_xlfn.MAXIFS(Sets!$H$2:$H$2000,Sets!$A$2:$A$2000,$A13,Sets!$D$2:$D$2000,I$1,Sets!$J$2:$J$2000,"N")) | ... AP13: =IF(_xlfn.MAXIFS(Sets!$H$2:$H$2000,Sets!$A$2:$A$2000,$A13,Sets!$D$2:$D$2000,AP$1,Sets!$J$2:$J$2000,"N")=0,"",_xlfn.MAXIFS(Sets!$H$2:$H$2000,Sets!$A$2:$A$2000,$A13,Sets!$D$2:$D$2000,AP$1,Sets!$J$2:$J$2000,"N"))
... A83: 46304 | B83: =IF(_xlfn.MAXIFS(Sets!$H$2:$H$2000,Sets!$A$2:$A$2000,$A83,Sets!$D$2:$D$2000,B$1,Sets!$J$2:$J$2000,"N")=0,"",_xlfn.MAXIFS(Sets!$H$2:$H$2000,Sets!$A$2:$A$2000,$A83,Sets!$D$2:$D$2000,B$1,Sets!$J$2:$J$2000,"N")) | C83: =IF(_xlfn.MAXIFS(Sets!$H$2:$H$2000,Sets!$A$2:$A$2000,$A83,Sets!$D$2:$D$2000,C$1,Sets!$J$2:$J$2000,"N")=0,"",_xlfn.MAXIFS(Sets!$H$2:$H$2000,Sets!$A$2:$A$2000,$A83,Sets!$D$2:$D$2000,C$1,Sets!$J$2:$J$2000,"N")) | D83: =IF(_xlfn.MAXIFS(Sets!$H$2:$H$2000,Sets!$A$2:$A$2000,$A83,Sets!$D$2:$D$2000,D$1,Sets!$J$2:$J$2000,"N")=0,"",_xlfn.MAXIFS(Sets!$H$2:$H$2000,Sets!$A$2:$A$2000,$A83,Sets!$D$2:$D$2000,D$1,Sets!$J$2:$J$2000,"N")) | E83: =IF(_xlfn.MAXIFS(Sets!$H$2:$H$2000,Sets!$A$2:$A$2000,$A83,Sets!$D$2:$D$2000,E$1,Sets!$J$2:$J$2000,"N")=0,"",_xlfn.MAXIFS(Sets!$H$2:$H$2000,Sets!$A$2:$A$2000,$A83,Sets!$D$2:$D$2000,E$1,Sets!$J$2:$J$2000,"N")) | F83: =IF(_xlfn.MAXIFS(Sets!$H$2:$H$2000,Sets!$A$2:$A$2000,$A83,Sets!$D$2:$D$2000,F$1,Sets!$J$2:$J$2000,"N")=0,"",_xlfn.MAXIFS(Sets!$H$2:$H$2000,Sets!$A$2:$A$2000,$A83,Sets!$D$2:$D$2000,F$1,Sets!$J$2:$J$2000,"N")) | G83: =IF(_xlfn.MAXIFS(Sets!$H$2:$H$2000,Sets!$A$2:$A$2000,$A83,Sets!$D$2:$D$2000,G$1,Sets!$J$2:$J$2000,"N")=0,"",_xlfn.MAXIFS(Sets!$H$2:$H$2000,Sets!$A$2:$A$2000,$A83,Sets!$D$2:$D$2000,G$1,Sets!$J$2:$J$2000,"N")) | H83: =IF(_xlfn.MAXIFS(Sets!$H$2:$H$2000,Sets!$A$2:$A$2000,$A83,Sets!$D$2:$D$2000,H$1,Sets!$J$2:$J$2000,"N")=0,"",_xlfn.MAXIFS(Sets!$H$2:$H$2000,Sets!$A$2:$A$2000,$A83,Sets!$D$2:$D$2000,H$1,Sets!$J$2:$J$2000,"N")) | I83: =IF(_xlfn.MAXIFS(Sets!$H$2:$H$2000,Sets!$A$2:$A$2000,$A83,Sets!$D$2:$D$2000,I$1,Sets!$J$2:$J$2000,"N")=0,"",_xlfn.MAXIFS(Sets!$H$2:$H$2000,Sets!$A$2:$A$2000,$A83,Sets!$D$2:$D$2000,I$1,Sets!$J$2:$J$2000,"N")) | ... AP83: =IF(_xlfn.MAXIFS(Sets!$H$2:$H$2000,Sets!$A$2:$A$2000,$A83,Sets!$D$2:$D$2000,AP$1,Sets!$J$2:$J$2000,"N")=0,"",_xlfn.MAXIFS(Sets!$H$2:$H$2000,Sets!$A$2:$A$2000,$A83,Sets!$D$2:$D$2000,AP$1,Sets!$J$2:$J$2000,"N"))

Sheet PR Summary
A1: Exercise | B1: Equipment | C1: Unit | D1: Best Weight | E1: Reps @ Best | F1: Date First Hit | G1: Last Performed | H1: Top Weight Last Session | I1: Working Sets Logged | J1: Total Volume
A2: Squats | B2: Smith | C2: lbs | D2: =_xlfn.MAXIFS(Sets!$H$2:$H$2000,Sets!$D$2:$D$2000,$A2,Sets!$J$2:$J$2000,"N") | E2: =IFERROR(INDEX(Sets!$I$2:$I$2000,MATCH($A2&"|"&$D2,Sets!$L$2:$L$2000,0)),"") | F2: =IFERROR(INDEX(Sets!$A$2:$A$2000,MATCH($A2&"|"&$D2,Sets!$L$2:$L$2000,0)),"") | G2: =_xlfn.MAXIFS(Sets!$A$2:$A$2000,Sets!$D$2:$D$2000,$A2) | H2: =_xlfn.MAXIFS(Sets!$H$2:$H$2000,Sets!$D$2:$D$2000,$A2,Sets!$A$2:$A$2000,$G2,Sets!$J$2:$J$2000,"N") | I2: =COUNTIFS(Sets!$D$2:$D$2000,$A2,Sets!$J$2:$J$2000,"N") | J2: =SUMIFS(Sets!$K$2:$K$2000,Sets!$D$2:$D$2000,$A2,Sets!$J$2:$J$2000,"N")
A3: RDLs | B3: Smith | C3: lbs | D3: =_xlfn.MAXIFS(Sets!$H$2:$H$2000,Sets!$D$2:$D$2000,$A3,Sets!$J$2:$J$2000,"N") | E3: =IFERROR(INDEX(Sets!$I$2:$I$2000,MATCH($A3&"|"&$D3,Sets!$L$2:$L$2000,0)),"") | F3: =IFERROR(INDEX(Sets!$A$2:$A$2000,MATCH($A3&"|"&$D3,Sets!$L$2:$L$2000,0)),"") | G3: =_xlfn.MAXIFS(Sets!$A$2:$A$2000,Sets!$D$2:$D$2000,$A3) | H3: =_xlfn.MAXIFS(Sets!$H$2:$H$2000,Sets!$D$2:$D$2000,$A3,Sets!$A$2:$A$2000,$G3,Sets!$J$2:$J$2000,"N") | I3: =COUNTIFS(Sets!$D$2:$D$2000,$A3,Sets!$J$2:$J$2000,"N") | J3: =SUMIFS(Sets!$K$2:$K$2000,Sets!$D$2:$D$2000,$A3,Sets!$J$2:$J$2000,"N")
A4: Calf Raises (Smith) | B4: Smith | C4: lbs | D4: =_xlfn.MAXIFS(Sets!$H$2:$H$2000,Sets!$D$2:$D$2000,$A4,Sets!$J$2:$J$2000,"N") | E4: =IFERROR(INDEX(Sets!$I$2:$I$2000,MATCH($A4&"|"&$D4,Sets!$L$2:$L$2000,0)),"") | F4: =IFERROR(INDEX(Sets!$A$2:$A$2000,MATCH($A4&"|"&$D4,Sets!$L$2:$L$2000,0)),"") | G4: =_xlfn.MAXIFS(Sets!$A$2:$A$2000,Sets!$D$2:$D$2000,$A4) | H4: =_xlfn.MAXIFS(Sets!$H$2:$H$2000,Sets!$D$2:$D$2000,$A4,Sets!$A$2:$A$2000,$G4,Sets!$J$2:$J$2000,"N") | I4: =COUNTIFS(Sets!$D$2:$D$2000,$A4,Sets!$J$2:$J$2000,"N") | J4: =SUMIFS(Sets!$K$2:$K$2000,Sets!$D$2:$D$2000,$A4,Sets!$J$2:$J$2000,"N")
A5: Lunges | B5: Bodyweight | C5: BW | D5: =_xlfn.MAXIFS(Sets!$H$2:$H$2000,Sets!$D$2:$D$2000,$A5,Sets!$J$2:$J$2000,"N") | E5: =IFERROR(INDEX(Sets!$I$2:$I$2000,MATCH($A5&"|"&$D5,Sets!$L$2:$L$2000,0)),"") | F5: =IFERROR(INDEX(Sets!$A$2:$A$2000,MATCH($A5&"|"&$D5,Sets!$L$2:$L$2000,0)),"") | G5: =_xlfn.MAXIFS(Sets!$A$2:$A$2000,Sets!$D$2:$D$2000,$A5) | H5: =_xlfn.MAXIFS(Sets!$H$2:$H$2000,Sets!$D$2:$D$2000,$A5,Sets!$A$2:$A$2000,$G5,Sets!$J$2:$J$2000,"N") | I5: =COUNTIFS(Sets!$D$2:$D$2000,$A5,Sets!$J$2:$J$2000,"N") | J5: =SUMIFS(Sets!$K$2:$K$2000,Sets!$D$2:$D$2000,$A5,Sets!$J$2:$J$2000,"N")
A6: Bench Press (DB) | B6: Dumbbell | C6: lbs | D6: =_xlfn.MAXIFS(Sets!$H$2:$H$2000,Sets!$D$2:$D$2000,$A6,Sets!$J$2:$J$2000,"N") | E6: =IFERROR(INDEX(Sets!$I$2:$I$2000,MATCH($A6&"|"&$D6,Sets!$L$2:$L$2000,0)),"") | F6: =IFERROR(INDEX(Sets!$A$2:$A$2000,MATCH($A6&"|"&$D6,Sets!$L$2:$L$2000,0)),"") | G6: =_xlfn.MAXIFS(Sets!$A$2:$A$2000,Sets!$D$2:$D$2000,$A6) | H6: =_xlfn.MAXIFS(Sets!$H$2:$H$2000,Sets!$D$2:$D$2000,$A6,Sets!$A$2:$A$2000,$G6,Sets!$J$2:$J$2000,"N") | I6: =COUNTIFS(Sets!$D$2:$D$2000,$A6,Sets!$J$2:$J$2000,"N") | J6: =SUMIFS(Sets!$K$2:$K$2000,Sets!$D$2:$D$2000,$A6,Sets!$J$2:$J$2000,"N")
A7: Single Arm Lat Pulldown | B7: Cable | C7: kg | D7: =_xlfn.MAXIFS(Sets!$H$2:$H$2000,Sets!$D$2:$D$2000,$A7,Sets!$J$2:$J$2000,"N") | E7: =IFERROR(INDEX(Sets!$I$2:$I$2000,MATCH($A7&"|"&$D7,Sets!$L$2:$L$2000,0)),"") | F7: =IFERROR(INDEX(Sets!$A$2:$A$2000,MATCH($A7&"|"&$D7,Sets!$L$2:$L$2000,0)),"") | G7: =_xlfn.MAXIFS(Sets!$A$2:$A$2000,Sets!$D$2:$D$2000,$A7) | H7: =_xlfn.MAXIFS(Sets!$H$2:$H$2000,Sets!$D$2:$D$2000,$A7,Sets!$A$2:$A$2000,$G7,Sets!$J$2:$J$2000,"N") | I7: =COUNTIFS(Sets!$D$2:$D$2000,$A7,Sets!$J$2:$J$2000,"N") | J7: =SUMIFS(Sets!$K$2:$K$2000,Sets!$D$2:$D$2000,$A7,Sets!$J$2:$J$2000,"N")
A8: Shoulder Press | B8: Dumbbell | C8: lbs | D8: =_xlfn.MAXIFS(Sets!$H$2:$H$2000,Sets!$D$2:$D$2000,$A8,Sets!$J$2:$J$2000,"N") | E8: =IFERROR(INDEX(Sets!$I$2:$I$2000,MATCH($A8&"|"&$D8,Sets!$L$2:$L$2000,0)),"") | F8: =IFERROR(INDEX(Sets!$A$2:$A$2000,MATCH($A8&"|"&$D8,Sets!$L$2:$L$2000,0)),"") | G8: =_xlfn.MAXIFS(Sets!$A$2:$A$2000,Sets!$D$2:$D$2000,$A8) | H8: =_xlfn.MAXIFS(Sets!$H$2:$H$2000,Sets!$D$2:$D$2000,$A8,Sets!$A$2:$A$2000,$G8,Sets!$J$2:$J$2000,"N") | I8: =COUNTIFS(Sets!$D$2:$D$2000,$A8,Sets!$J$2:$J$2000,"N") | J8: =SUMIFS(Sets!$K$2:$K$2000,Sets!$D$2:$D$2000,$A8,Sets!$J$2:$J$2000,"N")
A9: Bicep Curls (DB) | B9: Dumbbell | C9: lbs | D9: =_xlfn.MAXIFS(Sets!$H$2:$H$2000,Sets!$D$2:$D$2000,$A9,Sets!$J$2:$J$2000,"N") | E9: =IFERROR(INDEX(Sets!$I$2:$I$2000,MATCH($A9&"|"&$D9,Sets!$L$2:$L$2000,0)),"") | F9: =IFERROR(INDEX(Sets!$A$2:$A$2000,MATCH($A9&"|"&$D9,Sets!$L$2:$L$2000,0)),"") | G9: =_xlfn.MAXIFS(Sets!$A$2:$A$2000,Sets!$D$2:$D$2000,$A9) | H9: =_xlfn.MAXIFS(Sets!$H$2:$H$2000,Sets!$D$2:$D$2000,$A9,Sets!$A$2:$A$2000,$G9,Sets!$J$2:$J$2000,"N") | I9: =COUNTIFS(Sets!$D$2:$D$2000,$A9,Sets!$J$2:$J$2000,"N") | J9: =SUMIFS(Sets!$K$2:$K$2000,Sets!$D$2:$D$2000,$A9,Sets!$J$2:$J$2000,"N")
A10: DB Rows | B10: Dumbbell | C10: lbs | D10: =_xlfn.MAXIFS(Sets!$H$2:$H$2000,Sets!$D$2:$D$2000,$A10,Sets!$J$2:$J$2000,"N") | E10: =IFERROR(INDEX(Sets!$I$2:$I$2000,MATCH($A10&"|"&$D10,Sets!$L$2:$L$2000,0)),"") | F10: =IFERROR(INDEX(Sets!$A$2:$A$2000,MATCH($A10&"|"&$D10,Sets!$L$2:$L$2000,0)),"") | G10: =_xlfn.MAXIFS(Sets!$A$2:$A$2000,Sets!$D$2:$D$2000,$A10) | H10: =_xlfn.MAXIFS(Sets!$H$2:$H$2000,Sets!$D$2:$D$2000,$A10,Sets!$A$2:$A$2000,$G10,Sets!$J$2:$J$2000,"N") | I10: =COUNTIFS(Sets!$D$2:$D$2000,$A10,Sets!$J$2:$J$2000,"N") | J10: =SUMIFS(Sets!$K$2:$K$2000,Sets!$D$2:$D$2000,$A10,Sets!$J$2:$J$2000,"N")
A11: Tricep Ext Overhead | B11: Dumbbell | C11: lbs | D11: =_xlfn.MAXIFS(Sets!$H$2:$H$2000,Sets!$D$2:$D$2000,$A11,Sets!$J$2:$J$2000,"N") | E11: =IFERROR(INDEX(Sets!$I$2:$I$2000,MATCH($A11&"|"&$D11,Sets!$L$2:$L$2000,0)),"") | F11: =IFERROR(INDEX(Sets!$A$2:$A$2000,MATCH($A11&"|"&$D11,Sets!$L$2:$L$2000,0)),"") | G11: =_xlfn.MAXIFS(Sets!$A$2:$A$2000,Sets!$D$2:$D$2000,$A11) | H11: =_xlfn.MAXIFS(Sets!$H$2:$H$2000,Sets!$D$2:$D$2000,$A11,Sets!$A$2:$A$2000,$G11,Sets!$J$2:$J$2000,"N") | I11: =COUNTIFS(Sets!$D$2:$D$2000,$A11,Sets!$J$2:$J$2000,"N") | J11: =SUMIFS(Sets!$K$2:$K$2000,Sets!$D$2:$D$2000,$A11,Sets!$J$2:$J$2000,"N")
A12: Incline Flyes | B12: Dumbbell | C12: lbs | D12: =_xlfn.MAXIFS(Sets!$H$2:$H$2000,Sets!$D$2:$D$2000,$A12,Sets!$J$2:$J$2000,"N") | E12: =IFERROR(INDEX(Sets!$I$2:$I$2000,MATCH($A12&"|"&$D12,Sets!$L$2:$L$2000,0)),"") | F12: =IFERROR(INDEX(Sets!$A$2:$A$2000,MATCH($A12&"|"&$D12,Sets!$L$2:$L$2000,0)),"") | G12: =_xlfn.MAXIFS(Sets!$A$2:$A$2000,Sets!$D$2:$D$2000,$A12) | H12: =_xlfn.MAXIFS(Sets!$H$2:$H$2000,Sets!$D$2:$D$2000,$A12,Sets!$A$2:$A$2000,$G12,Sets!$J$2:$J$2000,"N") | I12: =COUNTIFS(Sets!$D$2:$D$2000,$A12,Sets!$J$2:$J$2000,"N") | J12: =SUMIFS(Sets!$K$2:$K$2000,Sets!$D$2:$D$2000,$A12,Sets!$J$2:$J$2000,"N")
A13: Smith Rows | B13: Smith | C13: lbs | D13: =_xlfn.MAXIFS(Sets!$H$2:$H$2000,Sets!$D$2:$D$2000,$A13,Sets!$J$2:$J$2000,"N") | E13: =IFERROR(INDEX(Sets!$I$2:$I$2000,MATCH($A13&"|"&$D13,Sets!$L$2:$L$2000,0)),"") | F13: =IFERROR(INDEX(Sets!$A$2:$A$2000,MATCH($A13&"|"&$D13,Sets!$L$2:$L$2000,0)),"") | G13: =_xlfn.MAXIFS(Sets!$A$2:$A$2000,Sets!$D$2:$D$2000,$A13) | H13: =_xlfn.MAXIFS(Sets!$H$2:$H$2000,Sets!$D$2:$D$2000,$A13,Sets!$A$2:$A$2000,$G13,Sets!$J$2:$J$2000,"N") | I13: =COUNTIFS(Sets!$D$2:$D$2000,$A13,Sets!$J$2:$J$2000,"N") | J13: =SUMIFS(Sets!$K$2:$K$2000,Sets!$D$2:$D$2000,$A13,Sets!$J$2:$J$2000,"N")
... A42: DB Flyes | B42: Dumbbell | C42: lbs | D42: =_xlfn.MAXIFS(Sets!$H$2:$H$2000,Sets!$D$2:$D$2000,$A42,Sets!$J$2:$J$2000,"N") | E42: =IFERROR(INDEX(Sets!$I$2:$I$2000,MATCH($A42&"|"&$D42,Sets!$L$2:$L$2000,0)),"") | F42: =IFERROR(INDEX(Sets!$A$2:$A$2000,MATCH($A42&"|"&$D42,Sets!$L$2:$L$2000,0)),"") | G42: =_xlfn.MAXIFS(Sets!$A$2:$A$2000,Sets!$D$2:$D$2000,$A42) | H42: =_xlfn.MAXIFS(Sets!$H$2:$H$2000,Sets!$D$2:$D$2000,$A42,Sets!$A$2:$A$2000,$G42,Sets!$J$2:$J$2000,"N") | I42: =COUNTIFS(Sets!$D$2:$D$2000,$A42,Sets!$J$2:$J$2000,"N") | J42: =SUMIFS(Sets!$K$2:$K$2000,Sets!$D$2:$D$2000,$A42,Sets!$J$2:$J$2000,"N")
A44: Notes
A45: Best Weight excludes warmup sets. Cable exercises are in kg; everything else in lbs.
A46: Bodyweight exercises show 0 - track those by reps in the Sets tab instead.
A47: Date First Hit = the earliest session at that weight, so a matched PR keeps its original date.
A48: Total Volume mixes kg and lbs across exercises, so compare it within an exercise, not between them.
A49: Assisted Pull-ups and Dips log ASSIST weight, so a LOWER number is the harder set - 'Best Weight' is inverted there.

Sheet Charts
A1: PROGRESSION CHARTS
A2: Top working weight per session. Gaps are sessions where the lift was not trained.
